Workbook

Sheet SPECIAL REQUEST
A1: Timestamp | B1: Branch | C1: Date | D1: To | E1: Purpose | F1: ITEM_ID | G1: Qty | H1: Unit | I1: Description | J1: UPrice | K1: Amount | L1: Total | M1: Requested By | N1: Status | O1: Release Date | P1: Received By | Q1: PDF URL
A2: 45971.055 | B2: WAREHOUSE | C2: 45971 | D2: PURCHASING OFFICE | E2: SPECIAL REQUEST | G2: 1 | H2: PC | I2: White Board | K2: 0 | L2: 0 | M2: Warehouse | N2: Approved | O2: 45971 | Q2: https://drive.google.com/file/d/1n1A1UTzNz-20b75jH0Y5AdjgSiagG7tA/view?usp=drivesdk
A3: 45973.994 | B3: TUBIGON | C3: 45960 | D3: PURCHASING OFFICE | E3: SPECIAL REQUEST | G3: 1 | H3: PC | I3: Chair | K3: 0 | L3: 0 | M3: TUBIGON | N3: Approved | O3: 45960 | Q3: https://drive.google.com/file/d/1hVy_a7MG8tjKZxKT0hb4MrFaxe_EXCMS/view?usp=drivesdk
A4: 45973.995 | B4: CLARIN | C4: 45960 | D4: PURCHASING OFFICE | E4: SPECIAL REQUEST | G4: 1 | H4: PC | I4: Brother Printer | K4: 0 | L4: 0 | M4: CLARIN | N4: Approved | O4: 45960 | Q4: https://drive.google.com/file/d/1UNkQa3s5U0xyq5xQJ8yCGuy1kqd0pxh4/view?usp=drivesdk
A5: 45973.996 | B5: WAREHOUSE | C5: 45932 | D5: PURCHASING OFFICE | E5: SPECIAL REQUEST | G5: 1 | H5: PC | I5: white board | K5: 0 | L5: 0 | M5: warehouse | N5: Approved | O5: 45932 | P5: Glenn | Q5: https://drive.google.com/file/d/1t6hSLMHJHJ3EI9D7qXWaq3WoO8QkeAFN/view?usp=drivesdk
A6: 45973.997 | B6: BULACAO | C6: 45932 | D6: PURCHASING OFFICE | E6: SPECIAL REQUEST | G6: 1 | H6: PC | I6: Bar Chair | K6: 0 | L6: 0 | M6: Bulacao | N6: Approved | O6: 45932 | Q6: https://drive.google.com/file/d/1Zs7O_1RMhToXNZgm5Fkzv0sn2-ZMRiqe/view?usp=drivesdk
A7: 45973.998 | B7: Y3S TALISAY | C7: 45932 | D7: PURCHASING OFFICE | E7: SPECIAL REQUEST | G7: 1 | H7: PC | I7: Bar Chair | K7: 0 | L7: 0 | M7: Y3S TALISAY | N7: Approved | O7: 45932 | P7: Ariel | Q7: https://drive.google.com/file/d/1C6cKHFFpTBofptivHQJo2g_KGtCnLZpm/view?usp=drivesdk
A8: 45973.999 | B8: BOGO | C8: 45929 | D8: PURCHASING OFFICE | E8: SPECIAL REQUEST | G8: 1 | H8: PC | I8: Money Detector | K8: 0 | L8: 0 | M8: BOGO | N8: Approved | O8: 45929 | P8: Kim | Q8: https://drive.google.com/file/d/1OC9cwNA3u5G8sDESN8z-KVBqWeZzLCeS/view?usp=drivesdk
A9: 45979.643 | B9: MINGLANILLA | C9: 45979 | D9: PURCHASING OFFICE | E9: SPECIAL REQUEST | G9: 1 | H9: BTL | I9: MURIATIC ACID | J9: 43.5 | K9: 43.5 | L9: 43.5 | M9: MINGLANILLA | N9: Approved | O9: 45980 | Q9: https://drive.google.com/file/d/1wZAH1FJD3vE4KRJMmSrNbjuWAYsm8BBn/view?usp=drivesdk
A10: 45982.399 | B10: BARILI MB | C10: 45982 | D10: PURCHASING OFFICE | E10: SPECIAL REQUEST | G10: 1 | I10: MOP | J10: 208 | K10: 208 | L10: 208 | M10: DARYL CLYDE DENILA | N10: Approved | O10: 45993 | Q10: https://drive.google.com/file/d/1nbSNHmGkihPWapA0MUiuJpX3KiA-4YCy/view?usp=drivesdk
A11: 45986.424 | B11: YATI LILOAN | C11: 45986 | D11: PURCHASING OFFICE | E11: SPECIAL REQUEST | G11: 1 | H11: PC | I11: Plastic Expandable Envelope w/ divider long | K11: 0 | L11: 0 | M11: YATI LIOAN | N11: Approved | O11: 45987 | Q11: https://drive.google.com/file/d/1vhjqe399oMgU19G7wyqoqeRaxjM3Dk90/view?usp=drivesdk
A12: 45988.398 | B12: YATI LILOAN | C12: 45982 | D12: PURCHASING OFFICE | E12: SPECIAL REQUEST | G12: 1 | H12: PC | I12: Money Bag (pencil pouch) | J12: 59 | K12: 59 | L12: 59 | M12: YATI LIOAN | N12: Approved | O12: 41238 | Q12: https://drive.google.com/file/d/1hR2FUKT3dZGNRViReU7Y_vDjhyDQVh_u/view?usp=drivesdk
A13: 45988.398 | B13: YATI LILOAN | C13: 45982 | D13: PURCHASING OFFICE | E13: SPECIAL REQUEST | G13: 1 | H13: PC | I13: FILE ORAGANIZER (FOR ACCOUNTANT) (Magazine Case) steel /book shelf | J13: 330 | K13: 330 | L13: 330 | M13: YATI LIOAN | N13: Approved | O13: 41238 | Q13: https://drive.google.com/file/d/1hR2FUKT3dZGNRViReU7Y_vDjhyDQVh_u/view?usp=drivesdk
A14: 45988.478 | B14: SIERRA BULLONES | C14: 45960 | D14: PURCHASING OFFICE | E14: SPECIAL REQUEST | G14: 1 | H14: PC | I14: TAPE DISPENSER | K14: 0 | L14: 0 | M14: SIERRA BULLONES | N14: Approved | O14: 45989 | Q14: https://drive.google.com/file/d/1NfsJh15vZlG7cXylBUF7_QQIkWC2VKVR/view?usp=drivesdk
A15: 45988.479 | B15: BACAYAN | C15: 45964 | D15: PURCHASING OFFICE | E15: SPECIAL REQUEST | G15: 4 | H15: PCS | I15: PUDLOCK | K15: 0 | L15: 0 | M15: BACAYAN | N15: Approved | O15: 41238 | Q15: https://drive.google.com/file/d/1WR-TKZI0MRvQgcBp4u2UJVGfFTytW8A7/view?usp=drivesdk
A16: 45988.482 | B16: BACAYAN | C16: 45979 | D16: PURCHASING OFFICE | E16: SPECIAL REQUEST | G16: 2 | H16: PCS | I16: FEATHER DUSTER | J16: 45 | K16: 45 | L16: 90 | M16: BACAYAN | N16: Approved | O16: 45993 | Q16: https://drive.google.com/file/d/1a0m0GQBXvzGjTO9cXZ54nspGK9BJeeHA/view?usp=drivesdk
A17: 45988.484 | B17: Y3S PARDO | C17: 45971 | D17: PURCHASING OFFICE | E17: SPECIAL REQUEST | G17: 1 | H17: PC | I17: FILER (CASHIER) PAHIGDA (Magazine Case) Steel | J17: 352 | K17: 352 | L17: 352 | M17: Y3S PARDO | N17: Approved | O17: 41238 | Q17: https://drive.google.com/file/d/1ixSV3oaVwGkGFgjhyqR3EI9gwu3yGblo/view?usp=drivesdk
A18: 45988.484 | B18: Y3S PARDO | C18: 45971 | D18: PURCHASING OFFICE | E18: SPECIAL REQUEST | G18: 2 | H18: PCS | I18: FILER ( LOANS) PATINDOG (Magazine Case) Steel /book shelf | J18: 330 | K18: 660 | L18: 660 | M18: Y3S PARDO | N18: Approved | O18: 41238 | Q18: https://drive.google.com/file/d/1ixSV3oaVwGkGFgjhyqR3EI9gwu3yGblo/view?usp=drivesdk
A19: 45988.717 | B19: CARMEN | C19: 45966 | D19: PURCHASING OFFICE | E19: SPECIAL REQUEST | G19: 10 | H19: PCS | I19: EXPANDED ENVELOPE | J19: 14 | K19: 140 | L19: 140 | M19: CARMEN | N19: Approved | O19: 45989 | Q19: https://drive.google.com/file/d/15zAF_9NPmyEz0XHjsK3m-9Hh1_8NMQwd/view?usp=drivesdk
A20: 45989.474 | B20: SIERRA BULLONES | C20: 45989 | D20: PURCHASING OFFICE | E20: SPECIAL REQUEST | G20: 1 | H20: PC | I20: Tool Box | J20: 752 | K20: 752 | L20: 794 | M20: SIERRA BULLONES | N20: Approved | O20: 45989 | Q20: https://drive.google.com/file/d/1xLAWybpV80_o0tMQWMA3dwa3b1YgAmgO/view?usp=drivesdk
A21: 45989.474 | B21: SIERRA BULLONES | C21: 45989 | D21: PURCHASING OFFICE | E21: SPECIAL REQUEST | G21: 1 | H21: PC | I21: ScrewDriver | J21: 42 | K21: 42 | L21: 794 | M21: SIERRA BULLONES | N21: Approved | O21: 45989 | Q21: https://drive.google.com/file/d/1xLAWybpV80_o0tMQWMA3dwa3b1YgAmgO/view?usp=drivesdk
A22: 45989.495 | B22: BULACAO | C22: 45989 | D22: PURCHASING OFFICE | E22: SPECIAL REQUEST | G22: 1 | H22: BLT | I22: MURIATIC ACID | J22: 43.5 | K22: 43.5 | L22: 43.5 | M22: Bulacao | N22: Approved | O22: 45989 | Q22: https://drive.google.com/file/d/1G80ZMCQF6ddiM6DjUhkwJOwCB0IqYwVe/view?usp=drivesdk
A23: 45992.471 | B23: BACAYAN | C23: 45989 | D23: PURCHASING OFFICE | E23: SPECIAL REQUEST | G23: 1 | H23: PC | I23: CUTTER | J23: 15 | K23: 15 | L23: 15 | M23: BACAYAN | N23: Approved | O23: 45993 | Q23: https://drive.google.com/file/d/1Dq22D_ecXUxnQi7dZZM2j57VfO7Xhh0b/view?usp=drivesdk
A24: 45992.471 | B24: BACAYAN | C24: 45989 | D24: PURCHASING OFFICE | E24: SPECIAL REQUEST | G24: 5 | H24: PCS | I24: STICK GLUE | J24: 6 | K24: 6 | L24: 30 | M24: BACAYAN | N24: Approved | O24: 45993 | Q24: https://drive.google.com/file/d/1Dq22D_ecXUxnQi7dZZM2j57VfO7Xhh0b/view?usp=drivesdk
A25: 45993.36 | B25: MINGLANILLA | C25: 45993 | D25: PURCHASING OFFICE | E25: SPECIAL REQUEST | G25: 1 | H25: PC | I25: WHITEBOARD ERASER | K25: 0 | L25: 0 | M25: JENIFE OLIVA | N25: Approved | O25: 45993 | Q25: https://drive.google.com/file/d/1EOv7iZoRSC_RdGptl65i3v_NHv-1l7fZ/view?usp=drivesdk
A26: 45993.686 | B26: Y3S BARILI | C26: 45984 | D26: PURCHASING OFFICE | E26: SPECIAL REQUEST | G26: 2 | H26: PCS | I26: MOP | J26: 208 | K26: 416 | L26: 416 | M26: Y3S BARILI | N26: Approved | O26: 45993 | Q26: https://drive.google.com/file/d/16uNShiAtLgdAoZqCCg4PIOf31sCV3SMQ/view?usp=drivesdk
A27: 45994.398 | B27: ADMIN | C27: 45994 | D27: PURCHASING OFFICE | E27: SPECIAL REQUEST | G27: 100 | H27: PCS | I27: Plastic medium (Para sa Sudlan sa Uniform) white | J27: 86.15 | K27: 86.15 | L27: 86.15 | M27: Ma'am Joy HR | N27: Approved | O27: 45995 | Q27: https://drive.google.com/file/d/1AU9A20MU8m_jfanAGO1iHt41W_Ij16OR/view?usp=drivesdk
A28: 45995.395 | B28: V-RAMA | C28: 45995 | D28: PURCHASING OFFICE | E28: SPECIAL REQUEST | G28: 3 | I28: USB (Cashier, Accountant, Loans) 32G | J28: 250 | K28: 750 | L28: 750 | M28: V-RAMA | N28: Approved | O28: 45995 | Q28: https://drive.google.com/file/d/1P773IJ2I_380ZtYCWyqQI7NCobLYatBl/view?usp=drivesdk
A29: 45995.397 | B29: ADMIN | C29: 45995 | D29: PURCHASING OFFICE | E29: SPECIAL REQUEST | G29: 1 | I29: USB 32G | J29: 250 | K29: 250 | L29: 250 | M29: Accounting Dept. | N29: Approved | O29: 45995 | Q29: https://drive.google.com/file/d/15no4SHnYFGy2LYz6Pic5G_7QhFeLaiNI/view?usp=drivesdk
A30: 45995.546 | B30: LAGTANG | C30: 45995 | D30: PURCHASING OFFICE | E30: SPECIAL REQUEST | G30: 3 | H30: PC | I30: YARN para sa yabe | J30: 8 | K30: 24 | L30: 24 | M30: LAGTANG | N30: Approved | O30: 45995 | Q30: https://drive.google.com/file/d/1pp8v9AvTu6gueoFvoHWD7JMV6snoIUf2/view?usp=drivesdk
A31: 45995.546 | B31: LAGTANG | C31: 45995 | D31: PURCHASING OFFICE | E31: SPECIAL REQUEST | G31: 1 | H31: PC | I31: Pen Holder w/ Divider ( Cashier) | J31: 96 | K31: 96 | L31: 96 | M31: LAGTANG | N31: Approved | O31: 45995 | Q31: https://drive.google.com/file/d/1pp8v9AvTu6gueoFvoHWD7JMV6snoIUf2/view?usp=drivesdk
A32: 46000.637 | B32: LILOAN | C32: 46000 | D32: PURCHASING OFFICE | E32: SPECIAL REQUEST | G32: 2 | H32: PCS | I32: File Rack/Vellum Organizer (Magazine Case) Steel / FILE CASE | J32: 360 | K32: 720 | L32: 720 | M32: LILOAN | N32: Approved | O32: 46000 | Q32: https://drive.google.com/file/d/1jQ6ugMZPD2NH47jGd-rn1YVNNAm-IMVl/view?usp=drivesdk
A33: 46000.692 | B33: TAYUD CONSOLACION | C33: 46000 | D33: PURCHASING OFFICE | E33: SPECIAL REQUEST | G33: 2 | H33: PCS | I33: File Rack/Vellum Organizer (Magazine Case) Steel / FILE CASE | J33: 360 | K33: 720 | L33: 720 | M33: Tayud Consolacion | N33: Approved | O33: 46000 | Q33: https://drive.google.com/file/d/1BNSnqcMFzBXSYQV_kzMp2EQces3ZrNFd/view?usp=drivesdk
A34: 46001.361 | B34: ADMIN | C34: 46001 | D34: PURCHASING OFFICE | E34: SPECIAL REQUEST | G34: 1 | H34: PC | I34: File Rack (Magazine Case) color Red Plastic | J34: 360 | K34: 360 | L34: 360 | M34: Ma'am Madi | N34: Approved | O34: 1/20/26 | Q34: https://drive.google.com/file/d/19wrXXlCRUWOU345j087vlu2tvyCQbSQh/view?usp=drivesdk
A35: 46001.658 | B35: ADMIN | C35: 46001 | D35: PURCHASING OFFICE | E35: SPECIAL REQUEST | G35: 5 | H35: PCS | I35: ID MAKER | J35: 30 | K35: 150 | L35: 150 | M35: IT DEPT | N35: Approved | Q35: https://drive.google.com/file/d/1MnFokygosY1ZTiVGl2k2GWNwT-Y52XY0/view?usp=drivesdk
A36: 46002.381 | B36: YATI LILOAN | C36: 46002 | D36: PURCHASING OFFICE | E36: SPECIAL REQUEST | G36: 5 | H36: PCS | I36: PLACTIC ENVELOPE (THICK) LONG BAGA GYUD | K36: 0 | L36: 0 | M36: YATI LIOAN | N36: Approved | O36: 12/30/25 | Q36: https://drive.google.com/file/d/1Ra0vvLkIPyiJHYnNqTKyaHHI6z5d2zfS/view?usp=drivesdk
A37: 46006.481 | B37: CARMEN | C37: 46006 | D37: PURCHASING OFFICE | E37: SPECIAL REQUEST | G37: 1 | H37: PC | I37: UV LIGHT BULB MONEY DETECTOR (CASHIER) | K37: 0 | L37: 0 | M37: CARMEN | N37: Approved | O37: 12/23/25 | Q37: https://drive.google.com/file/d/11ABwdJLv9fCMtGJ86xl75X8FblG3LE_B/view?usp=drivesdk
A38: 46006.481 | B38: CARMEN | C38: 46006 | D38: PURCHASING OFFICE | E38: SPECIAL REQUEST | G38: 1 | H38: PC | I38: CASH BOX (CASHIER) | J38: 600 | K38: 600 | L38: 600 | M38: CARMEN | N38: To Buy | Q38: https://drive.google.com/file/d/11ABwdJLv9fCMtGJ86xl75X8FblG3LE_B/view?usp=drivesdk
A39: 46006.481 | B39: CARMEN | C39: 46006 | D39: PURCHASING OFFICE | E39: SPECIAL REQUEST | G39: 9 | H39: PCS | I39: DOOR MAT | J39: 35 | K39: 300 | L39: 300 | M39: CARMEN | N39: Approved | O39: 46357 | Q39: https://drive.google.com/file/d/11ABwdJLv9fCMtGJ86xl75X8FblG3LE_B/view?usp=drivesdk
A40: 46006.481 | B40: CARMEN | C40: 46006 | D40: PURCHASING OFFICE | E40: SPECIAL REQUEST | G40: 1 | H40: PC | I40: MORNING EVOTIONAL FOR NEXT YEAR (BISAYA) | K40: 0 | L40: 0 | M40: CARMEN | N40: Approved | O40: 12/23/25 | Q40: https://drive.google.com/file/d/11ABwdJLv9fCMtGJ86xl75X8FblG3LE_B/view?usp=drivesdk
...

Sheet Accouting Dept

Sheet To Buy

Sheet BRANCH LIST
A1: Branch_ID | B1: Branch | C1: Email
A2: AD001 | B2: ADMIN | C2: gmpcpurchasing@gmail.com
A3: WH002 | B3: WAREHOUSE | C3: warehousegiant21@gmail.com
A4: BR001 | B4: LAGTANG | C4: giantmotoprolagtang@gmail.com
A5: BR002 | B5: V-RAMA | C5: gmpcguad_accounting@yahoo.com.ph
A6: BR003 | B6: BULACAO | C6: ivyhamistoso@gmail.com
A7: BR004 | B7: Y3S TALISAY | C7: gmpcyamaha3st@gmail.com
A8: BR005 | B8: MINGLANILLA | C8: giantmotoprolinao@gmail.com
A9: BR006 | B9: Y3S PARDO | C9: gmpcy3spardo@yahoo.com
A10: BR007 | B10: LAPU-LAPU | C10: giantmotoproopon19@gmail.com
A11: BR008 | B11: BACAYAN | C11: gmpcbacayan@gmail.com
A12: BR009 | B12: SAN FERNANDO MB | C12: gmpcsanfernando@gmail.com
... A32: BR029 | B32: YATI LILOAN | C32: gmpcyatililoan@gmail.com
A33: BR030 | B33: CAMOTES

Sheet SUMMARY
A1: Branch | B1: ITEM_ID | C1: Description | D1: Total Qty | E1: Total Amount | F1: Timestamp
A2: =IFERROR(__xludf.DUMMYFUNCTION("ARRAYFORMULA( QUERY( { IFERROR(FILTER(ADMIN!B:B, ADMIN!N:N=""Approved"")), IFERROR(FILTER(ADMIN!F:F, ADMIN!N:N=""Approved"")), IFERROR(FILTER(ADMIN!I:I, ADMIN!N:N=""Approved"")), IFERROR(FILTER(ADMIN!G:G, ADMIN!N:N=""Approved"&""")), IFERROR(FILTER(ADMIN!K:K, ADMIN!N:N=""Approved"")); IFERROR(FILTER(WAREHOUSE!B:B, WAREHOUSE!N:N=""Approved"")), IFERROR(FILTER(WAREHOUSE!F:F, WAREHOUSE!N:N=""Approved"")), IFERROR(FILTER(WAREHOUSE!I:I, WAREHOUSE!N:N="""&"Approved"")), IFERROR(FILTER(WAREHOUSE!G:G, WAREHOUSE!N:N=""Approved"")), IFERROR(FILTER(WAREHOUSE!K:K, WAREHOUSE!N:N=""Approved"")); IFERROR(FILTER(LAGTANG!B:B, LAGTANG!N:N=""Approved"")), IFERROR(FILTER(LAGTANG!F:F, LAGTAN"&"G!N:N=""Approved"")), IFERROR(FILTER(LAGTANG!I:I, LAGTANG!N:N=""Approved"")), IFERROR(FILTER(LAGTANG!G:G, LAGTANG!N:N=""Approved"")), IFERROR(FILTER(LAGTANG!K:K, LAGTANG!N:N=""Approved"")); IFERROR(FILTER('V-RAMA'!B:B, 'V-RA"&"MA'!N:N=""Approved"")), IFERROR(FILTER('V-RAMA'!F:F, 'V-RAMA'!N:N=""Approved"")), IFERROR(FILTER('V-RAMA'!I:I, 'V-RAMA'!N:N=""Approved"")), IFERROR(FILTER('V-RAMA'!G:G, 'V-RAMA'!N:N=""Approved"")), IFERROR(FILTER('V-RAMA'!K:K, 'V-R"&"AMA'!N:N=""Approved"")); IFERROR(FILTER(BULACAO!B:B, BULACAO!N:N=""Approved"")), IFERROR(FILTER(BULACAO!F:F, BULACAO!N:N=""Approved"")), IFERROR(FILTER(BULACAO!I:I, BULACAO!N:N=""Approved"")), IFERROR(FILTER(BULACAO!G:G, BUL"&"ACAO!N:N=""Approved"")), IFERROR(FILTER(BULACAO!K:K, BULACAO!N:N=""Approved"")); IFERROR(FILTER('Y3S TALISAY'!B:B, 'Y3S TALISAY'!N:N=""Approved"")), IFERROR(FILTER('Y3S TALISAY'!F:F, 'Y3S TALISAY'!N:N=""Approved"")), IFERROR"&"(FILTER('Y3S TALISAY'!I:I, 'Y3S TALISAY'!N:N=""Approved"")), IFERROR(FILTER('Y3S TALISAY'!G:G, 'Y3S TALISAY'!N:N=""Approved"")), IFERROR(FILTER('Y3S TALISAY'!K:K, 'Y3S TALISAY'!N:N=""Approved"")); IFERROR(FILTER(MINGLANILLA!B:B, M"&"INGLANILLA!N:N=""Approved"")), IFERROR(FILTER(MINGLANILLA!F:F, MINGLANILLA!N:N=""Approved"")), IFERROR(FILTER(MINGLANILLA!I:I, MINGLANILLA!N:N=""Approved"")), IFERROR(FILTER(MINGLANILLA!G:G, MINGLANILLA!N:N=""Approved"")), IFERROR("&"FILTER(MINGLANILLA!K:K, MINGLANILLA!N:N=""Approved"")); IFERROR(FILTER('Y3S PARDO'!B:B, 'Y3S PARDO'!N:N=""Approved"")), IFERROR(FILTER('Y3S PARDO'!F:F, 'Y3S PARDO'!N:N=""Approved"")), IFERROR(FILTER('Y3S PARDO'!I:I, 'Y3S PARDO'!N:"&"N=""Approved"")), IFERROR(FILTER('Y3S PARDO'!G:G, 'Y3S PARDO'!N:N=""Approved"")), IFERROR(FILTER('Y3S PARDO'!K:K, 'Y3S PARDO'!N:N=""Approved"")); IFERROR(FILTER('LAPU-LAPU'!B:B, 'LAPU-LAPU'!N:N=""Approved"")), IFERROR(FILTER"&"('LAPU-LAPU'!F:F, 'LAPU-LAPU'!N:N=""Approved"")), IFERROR(FILTER('LAPU-LAPU'!I:I, 'LAPU-LAPU'!N:N=""Approved"")), IFERROR(FILTER('LAPU-LAPU'!G:G, 'LAPU-LAPU'!N:N=""Approved"")), IFERROR(FILTER('LAPU-LAPU'!K:K, 'LAPU-LAPU'!N:N=""Approved"&""")); IFERROR(FILTER(BACAYAN!B:B, BACAYAN!N:N=""Approved"")), IFERROR(FILTER(BACAYAN!F:F, BACAYAN!N:N=""Approved"")), IFERROR(FILTER(BACAYAN!I:I, BACAYAN!N:N=""Approved"")), IFERROR(FILTER(BACAYAN!G:G, BACAYAN!N:N=""Approved"&""")), IFERROR(FILTER(BACAYAN!K:K, BACAYAN!N:N=""Approved"")); IFERROR(FILTER('SAN FERNANDO MB'!B:B, 'SAN FERNANDO MB'!N:N=""Approved"")), IFERROR(FILTER('SAN FERNANDO MB'!F:F, 'SAN FERNANDO MB'!N:N=""Approved"")), IFERROR(FI"&"LTER('SAN FERNANDO MB'!I:I, 'SAN FERNANDO MB'!N:N=""Approved"")), IFERROR(FILTER('SAN FERNANDO MB'!G:G, 'SAN FERNANDO MB'!N:N=""Approved"")), IFERROR(FILTER('SAN FERNANDO MB'!K:K, 'SAN FERNANDO MB'!N:N=""Approved"")); IFERROR(FILT"&"ER('Y3S SAN FERNANDO'!B:B, 'Y3S SAN FERNANDO'!N:N=""Approved"")), IFERROR(FILTER('Y3S SAN FERNANDO'!F:F, 'Y3S SAN FERNANDO'!N:N=""Approved"")), IFERROR(FILTER('Y3S SAN FERNANDO'!I:I, 'Y3S SAN FERNANDO'!N:N=""Approved"")), IFERROR(FILTER("&"'Y3S SAN FERNANDO'!G:G, 'Y3S SAN FERNANDO'!N:N=""Approved"")), IFERROR(FILTER('Y3S SAN FERNANDO'!K:K, 'Y3S SAN FERNANDO'!N:N=""Approved"")); IFERROR(FILTER(LILOAN!B:B, LILOAN!N:N=""Approved"")), IFERROR(FILTER(LILOAN!F:F, LILOAN!N"&":N=""Approved"")), IFERROR(FILTER(LILOAN!I:I, LILOAN!N:N=""Approved"")), IFERROR(FILTER(LILOAN!G:G, LILOAN!N:N=""Approved"")), IFERROR(FILTER(LILOAN!K:K, LILOAN!N:N=""Approved"")); IFERROR(FILTER('CORDOVA MB'!B:B, 'CORDOVA M"&"B'!N:N=""Approved"")), IFERROR(FILTER('CORDOVA MB'!F:F, 'CORDOVA MB'!N:N=""Approved"")), IFERROR(FILTER('CORDOVA MB'!I:I, 'CORDOVA MB'!N:N=""Approved"")), IFERROR(FILTER('CORDOVA MB'!G:G, 'CORDOVA MB'!N:N=""Approved"")), IFERROR(FI"&"LTER('CORDOVA MB'!K:K, 'CORDOVA MB'!N:N=""Approved"")); IFERROR(FILTER('Y3S CORDOVA'!B:B, 'Y3S CORDOVA'!N:N=""Approved"")), IFERROR(FILTER('Y3S CORDOVA'!F:F, 'Y3S CORDOVA'!N:N=""Approved"")), IFERROR(FILTER('Y3S CORDOVA'!I:I, 'Y3S"&" CORDOVA'!N:N=""Approved"")), IFERROR(FILTER('Y3S CORDOVA'!G:G, 'Y3S CORDOVA'!N:N=""Approved"")), IFERROR(FILTER('Y3S CORDOVA'!K:K, 'Y3S CORDOVA'!N:N=""Approved"")); IFERROR(FILTER(CLARIN!B:B, CLARIN!N:N=""Approved"")), IFER"&"ROR(FILTER(CLARIN!F:F, CLARIN!N:N=""Approved"")), IFERROR(FILTER(CLARIN!I:I, CLARIN!N:N=""Approved"")), IFERROR(FILTER(CLARIN!G:G, CLARIN!N:N=""Approved"")), IFERROR(FILTER(CLARIN!K:K, CLARIN!N:N=""Approved"")); IFERROR(FILT"&"ER(TOLEDO!B:B, TOLEDO!N:N=""Approved"")), IFERROR(FILTER(TOLEDO!F:F, TOLEDO!N:N=""Approved"")), IFERROR(FILTER(TOLEDO!I:I, TOLEDO!N:N=""Approved"")), IFERROR(FILTER(TOLEDO!G:G, TOLEDO!N:N=""Approved"")), IFERROR(FILTER(TOLEDO!K:K, "&"TOLEDO!N:N=""Approved"")); IFERROR(FILTER(UBAY!B:B, UBAY!N:N=""Approved"")), IFERROR(FILTER(UBAY!F:F, UBAY!N:N=""Approved"")), IFERROR(FILTER(UBAY!I:I, UBAY!N:N=""Approved"")), IFERROR(FILTER(UBAY!G:G, UBAY!N:N=""Approved"")"&"), IFERROR(FILTER(UBAY!K:K, UBAY!N:N=""Approved"")); IFERROR(FILTER(CARMEN!B:B, CARMEN!N:N=""Approved"")), IFERROR(FILTER(CARMEN!F:F, CARMEN!N:N=""Approved"")), IFERROR(FILTER(CARMEN!I:I, CARMEN!N:N=""Approved"")), IFE"&"RROR(FILTER(CARMEN!G:G, CARMEN!N:N=""Approved"")), IFERROR(FILTER(CARMEN!K:K, CARMEN!N:N=""Approved"")); IFERROR(FILTER(TUBIGON!B:B, TUBIGON!N:N=""Approved"")), IFERROR(FILTER(TUBIGON!F:F, TUBIGON!N:N=""Approved"")), IFERROR"&"(FILTER(TUBIGON!I:I, TUBIGON!N:N=""Approved"")), IFERROR(FILTER(TUBIGON!G:G, TUBIGON!N:N=""Approved"")), IFERROR(FILTER(TUBIGON!K:K, TUBIGON!N:N=""Approved"")); IFERROR(FILTER(TALIBON!B:B, TALIBON!N:N=""Approved"")), IFERROR"&"(FILTER(TALIBON!F:F, TALIBON!N:N=""Approved"")), IFERROR(FILTER(TALIBON!I:I, TALIBON!N:N=""Approved"")), IFERROR(FILTER(TALIBON!G:G, TALIBON!N:N=""Approved"")), IFERROR(FILTER(TALIBON!K:K, TALIBON!N:N=""Approved"")); IFERROR"&"(FILTER(BOGO!B:B, BOGO!N:N=""Approved"")), IFERROR(FILTER(BOGO!F:F, BOGO!N:N=""Approved"")), IFERROR(FILTER(BOGO!I:I, BOGO!N:N=""Approved"")), IFERROR(FILTER(BOGO!G:G, BOGO!N:N=""Approved"")), IFERROR(FILTER(BOGO!K:K, BOGO!N:N=""Ap"&"proved"")); IFERROR(FILTER(BALAMBAN!B:B, BALAMBAN!N:N=""Approved"")), IFERROR(FILTER(BALAMBAN!F:F, BALAMBAN!N:N=""Approved"")), IFERROR(FILTER(BALAMBAN!I:I, BALAMBAN!N:N=""Approved"")), IFERROR(FILTER(BALAMBAN!G:G, BALAMBAN!"&"N:N=""Approved"")), IFERROR(FILTER(BALAMBAN!K:K, BALAMBAN!N:N=""Approved"")); IFERROR(FILTER('Y3S BARILI'!B:B, 'Y3S BARILI'!N:N=""Approved"")), IFERROR(FILTER('Y3S BARILI'!F:F, 'Y3S BARILI'!N:N=""Approved"")), IFERROR(FILTER"&"('Y3S BARILI'!I:I, 'Y3S BARILI'!N:N=""Approved"")), IFERROR(FILTER('Y3S BARILI'!G:G, 'Y3S BARILI'!N:N=""Approved"")), IFERROR(FILTER('Y3S BARILI'!K:K, 'Y3S BARILI'!N:N=""Approved"")); IFERROR(FILTER('BARILI MB'!B:B, 'BARILI MB'!N:"&"N=""Approved"")), IFERROR(FILTER('BARILI MB'!F:F, 'BARILI MB'!N:N=""Approved"")), IFERROR(FILTER('BARILI MB'!I:I, 'BARILI MB'!N:N=""Approved"")), IFERROR(FILTER('BARILI MB'!G:G, 'BARILI MB'!N:N=""Approved"")), IFERROR(FILTER('BARIL"&"I MB'!K:K, 'BARILI MB'!N:N=""Approved"")); IFERROR(FILTER('SIERRA BULLONES'!B:B, 'SIERRA BULLONES'!N:N=""Approved"")), IFERROR(FILTER('SIERRA BULLONES'!F:F, 'SIERRA BULLONES'!N:N=""Approved"")), IFERROR(FILTER('SIERRA BULLONES'!I:"&"I, 'SIERRA BULLONES'!N:N=""Approved"")), IFERROR(FILTER('SIERRA BULLONES'!G:G, 'SIERRA BULLONES'!N:N=""Approved"")), IFERROR(FILTER('SIERRA BULLONES'!K:K, 'SIERRA BULLONES'!N:N=""Approved"")); IFERROR(FILTER(PITOGO!B:B, PITOGO!N:N"&"=""Approved"")), IFERROR(FILTER(PITOGO!F:F, PITOGO!N:N=""Approved"")), IFERROR(FILTER(PITOGO!I:I, PITOGO!N:N=""Approved"")), IFERROR(FILTER(PITOGO!G:G, PITOGO!N:N=""Approved"")), IFERROR(FILTER(PITOGO!K:K, PITOGO!N:N=""Approved""))"&"; IFERROR(FILTER('TAYUD CONSOLACION'!B:B, 'TAYUD CONSOLACION'!N:N=""Approved"")), IFERROR(FILTER('TAYUD CONSOLACION'!F:F, 'TAYUD CONSOLACION'!N:N=""Approved"")), IFERROR(FILTER('TAYUD CONSOLACION'!I:I, 'TAYUD CONSOLACION'!N:N=""Ap"&"proved"")), IFERROR(FILTER('TAYUD CONSOLACION'!G:G, 'TAYUD CONSOLACION'!N:N=""Approved"")), IFERROR(FILTER('TAYUD CONSOLACION'!K:K, 'TAYUD CONSOLACION'!N:N=""Approved"")); IFERROR(FILTER(PINAMUNGAJAN!B:B, PINAMUNGAJAN!N:N=""Approv"&"ed"")), IFERROR(FILTER(PINAMUNGAJAN!F:F, PINAMUNGAJAN!N:N=""Approved"")), IFERROR(FILTER(PINAMUNGAJAN!I:I, PINAMUNGAJAN!N:N=""Approved"")), IFERROR(FILTER(PINAMUNGAJAN!G:G, PINAMUNGAJAN!N:N=""Approved"")), IFERROR(FILTER(PINAMUNGAJ"&"AN!K:K, PINAMUNGAJAN!N:N=""Approved"")); IFERROR(FILTER(CANDIJAY!B:B, CANDIJAY!N:N=""Approved"")), IFERROR(FILTER(CANDIJAY!F:F, CANDIJAY!N:N=""Approved"")), IFERROR(FILTER(CANDIJAY!I:I, CANDIJAY!N:N=""Approved"")), IFERROR(F"&"ILTER(CANDIJAY!G:G, CANDIJAY!N:N=""Approved"")), IFERROR(FILTER(CANDIJAY!K:K, CANDIJAY!N:N=""Approved"")); IFERROR(FILTER('YATI LILOAN'!B:B, 'YATI LILOAN'!N:N=""Approved"")), IFERROR(FILTER('YATI LILOAN'!F:F, 'YATI LILOAN'!N:N=""A"&"pproved"")), IFERROR(FILTER('YATI LILOAN'!I:I, 'YATI LILOAN'!N:N=""Approved"")), IFERROR(FILTER('YATI LILOAN'!G:G, 'YATI LILOAN'!N:N=""Approved"")), IFERROR(FILTER('YATI LILOAN'!K:K, 'YATI LILOAN'!N:N=""Approved"")); IFERROR("&"FILTER(CAMOTES!B:B, CAMOTES!N:N=""Approved"")), IFERROR(FILTER(CAMOTES!F:F, CAMOTES!N:N=""Approved"")), IFERROR(FILTER(CAMOTES!I:I, CAMOTES!N:N=""Approved"")), IFERROR(FILTER(CAMOTES!G:G, CAMOTES!N:N=""Approved"")), IFERROR(FILTER("&"CAMOTES!K:K, CAMOTES!N:N=""Approved"")) }, ""select * where Col1 is not null"" ) )"),"ADMIN") -> ADMIN | B2: =IFERROR(__xludf.DUMMYFUNCTION("""COMPUTED_VALUE"""),"ITM007") -> ITM007 | C2: =IFERROR(__xludf.DUMMYFUNCTION("""COMPUTED_VALUE"""),"LOGBOOK VALIANT RECORD (150 & 300P PAGES)") -> LOGBOOK VALIANT RECORD (150 & 300P PAGES) | D2: =IFERROR(__xludf.DUMMYFUNCTION("""COMPUTED_VALUE"""),1.0) -> 1 | E2: =IFERROR(__xludf.DUMMYFUNCTION("""COMPUTED_VALUE"""),0.0) -> 0
A3: =IFERROR(__xludf.DUMMYFUNCTION("""COMPUTED_VALUE"""),"ADMIN") -> ADMIN | B3: =IFERROR(__xludf.DUMMYFUNCTION("""COMPUTED_VALUE"""),"ITM003") -> ITM003 | C3: =IFERROR(__xludf.DUMMYFUNCTION("""COMPUTED_VALUE"""),"BOND PAPER A4") -> BOND PAPER A4 | D3: =IFERROR(__xludf.DUMMYFUNCTION("""COMPUTED_VALUE"""),1.0) -> 1 | E3: =IFERROR(__xludf.DUMMYFUNCTION("""COMPUTED_VALUE"""),0.0) -> 0
A4: =IFERROR(__xludf.DUMMYFUNCTION("""COMPUTED_VALUE"""),"ADMIN") -> ADMIN | B4: =IFERROR(__xludf.DUMMYFUNCTION("""COMPUTED_VALUE"""),"ITM001") -> ITM001 | C4: =IFERROR(__xludf.DUMMYFUNCTION("""COMPUTED_VALUE"""),"BOND PAPER (LONG)") -> BOND PAPER (LONG) | D4: =IFERROR(__xludf.DUMMYFUNCTION("""COMPUTED_VALUE"""),1.0) -> 1 | E4: =IFERROR(__xludf.DUMMYFUNCTION("""COMPUTED_VALUE"""),0.0) -> 0
A5: =IFERROR(__xludf.DUMMYFUNCTION("""COMPUTED_VALUE"""),"ADMIN") -> ADMIN | B5: =IFERROR(__xludf.DUMMYFUNCTION("""COMPUTED_VALUE"""),"ITM023") -> ITM023 | C5: =IFERROR(__xludf.DUMMYFUNCTION("""COMPUTED_VALUE"""),"HIGHLIGHTER") -> HIGHLIGHTER | D5: =IFERROR(__xludf.DUMMYFUNCTION("""COMPUTED_VALUE"""),1.0) -> 1 | E5: =IFERROR(__xludf.DUMMYFUNCTION("""COMPUTED_VALUE"""),0.0) -> 0
A6: =IFERROR(__xludf.DUMMYFUNCTION("""COMPUTED_VALUE"""),"ADMIN") -> ADMIN | B6: =IFERROR(__xludf.DUMMYFUNCTION("""COMPUTED_VALUE"""),"ITM002") -> ITM002 | C6: =IFERROR(__xludf.DUMMYFUNCTION("""COMPUTED_VALUE"""),"BOND PAPER (SHORT)") -> BOND PAPER (SHORT) | D6: =IFERROR(__xludf.DUMMYFUNCTION("""COMPUTED_VALUE"""),1.0) -> 1 | E6: =IFERROR(__xludf.DUMMYFUNCTION("""COMPUTED_VALUE"""),0.0) -> 0
A7: =IFERROR(__xludf.DUMMYFUNCTION("""COMPUTED_VALUE"""),"ADMIN") -> ADMIN | B7: =IFERROR(__xludf.DUMMYFUNCTION("""COMPUTED_VALUE"""),"ITM031") -> ITM031 | C7: =IFERROR(__xludf.DUMMYFUNCTION("""COMPUTED_VALUE"""),"SCISSORS") -> SCISSORS | D7: =IFERROR(__xludf.DUMMYFUNCTION("""COMPUTED_VALUE"""),1.0) -> 1 | E7: =IFERROR(__xludf.DUMMYFUNCTION("""COMPUTED_VALUE"""),0.0) -> 0
A8: =IFERROR(__xludf.DUMMYFUNCTION("""COMPUTED_VALUE"""),"ADMIN") -> ADMIN | B8: =IFERROR(__xludf.DUMMYFUNCTION("""COMPUTED_VALUE"""),"ITM027") -> ITM027 | C8: =IFERROR(__xludf.DUMMYFUNCTION("""COMPUTED_VALUE"""),"CORRECTION TAPE") -> CORRECTION TAPE | D8: =IFERROR(__xludf.DUMMYFUNCTION("""COMPUTED_VALUE"""),1.0) -> 1 | E8: =IFERROR(__xludf.DUMMYFUNCTION("""COMPUTED_VALUE"""),0.0) -> 0
A9: =IFERROR(__xludf.DUMMYFUNCTION("""COMPUTED_VALUE"""),"ADMIN") -> ADMIN | B9: =IFERROR(__xludf.DUMMYFUNCTION("""COMPUTED_VALUE"""),"ITM019") -> ITM019 | C9: =IFERROR(__xludf.DUMMYFUNCTION("""COMPUTED_VALUE"""),"FLEXSTICK BLACK BALLPEN (0.5)") -> FLEXSTICK BLACK BALLPEN (0.5) | D9: =IFERROR(__xludf.DUMMYFUNCTION("""COMPUTED_VALUE"""),1.0) -> 1 | E9: =IFERROR(__xludf.DUMMYFUNCTION("""COMPUTED_VALUE"""),0.0) -> 0
A10: =IFERROR(__xludf.DUMMYFUNCTION("""COMPUTED_VALUE"""),"ADMIN") -> ADMIN | B10: =IFERROR(__xludf.DUMMYFUNCTION("""COMPUTED_VALUE"""),"ITM020") -> ITM020 | C10: =IFERROR(__xludf.DUMMYFUNCTION("""COMPUTED_VALUE"""),"FLEXSTICK RED BALLPEN (0.5)") -> FLEXSTICK RED BALLPEN (0.5) | D10: =IFERROR(__xludf.DUMMYFUNCTION("""COMPUTED_VALUE"""),1.0) -> 1 | E10: =IFERROR(__xludf.DUMMYFUNCTION("""COMPUTED_VALUE"""),0.0) -> 0
A11: =IFERROR(__xludf.DUMMYFUNCTION("""COMPUTED_VALUE"""),"ADMIN") -> ADMIN | B11: =IFERROR(__xludf.DUMMYFUNCTION("""COMPUTED_VALUE"""),"ITM031") -> ITM031 | C11: =IFERROR(__xludf.DUMMYFUNCTION("""COMPUTED_VALUE"""),"SCISSORS") -> SCISSORS | D11: =IFERROR(__xludf.DUMMYFUNCTION("""COMPUTED_VALUE"""),1.0) -> 1 | E11: =IFERROR(__xludf.DUMMYFUNCTION("""COMPUTED_VALUE"""),0.0) -> 0
A12: =IFERROR(__xludf.DUMMYFUNCTION("""COMPUTED_VALUE"""),"ADMIN") -> ADMIN | B12: =IFERROR(__xludf.DUMMYFUNCTION("""COMPUTED_VALUE"""),"ITM034") -> ITM034 | C12: =IFERROR(__xludf.DUMMYFUNCTION("""COMPUTED_VALUE"""),"CALCULATOR MX-12B") -> CALCULATOR MX-12B | D12: =IFERROR(__xludf.DUMMYFUNCTION("""COMPUTED_VALUE"""),1.0) -> 1 | E12: =IFERROR(__xludf.DUMMYFUNCTION("""COMPUTED_VALUE"""),0.0) -> 0
A13: =IFERROR(__xludf.DUMMYFUNCTION("""COMPUTED_VALUE"""),"ADMIN") -> ADMIN | B13: =IFERROR(__xludf.DUMMYFUNCTION("""COMPUTED_VALUE"""),"ITM074") -> ITM074 | C13: =IFERROR(__xludf.DUMMYFUNCTION("""COMPUTED_VALUE"""),"STAPLE WIRE #35") -> STAPLE WIRE #35 | D13: =IFERROR(__xludf.DUMMYFUNCTION("""COMPUTED_VALUE"""),1.0) -> 1 | E13: =IFERROR(__xludf.DUMMYFUNCTION("""COMPUTED_VALUE"""),0.0) -> 0
A14: =IFERROR(__xludf.DUMMYFUNCTION("""COMPUTED_VALUE"""),"ADMIN") -> ADMIN | B14: =IFERROR(__xludf.DUMMYFUNCTION("""COMPUTED_VALUE"""),"ITM030") -> ITM030 | C14: =IFERROR(__xludf.DUMMYFUNCTION("""COMPUTED_VALUE"""),"STAPLER") -> STAPLER | D14: =IFERROR(__xludf.DUMMYFUNCTION("""COMPUTED_VALUE"""),1.0) -> 1 | E14: =IFERROR(__xludf.DUMMYFUNCTION("""COMPUTED_VALUE"""),0.0) -> 0
A15: =IFERROR(__xludf.DUMMYFUNCTION("""COMPUTED_VALUE"""),"ADMIN") -> ADMIN | B15: =IFERROR(__xludf.DUMMYFUNCTION("""COMPUTED_VALUE"""),"ITM002") -> ITM002 | C15: =IFERROR(__xludf.DUMMYFUNCTION("""COMPUTED_VALUE"""),"BOND PAPER (SHORT)") -> BOND PAPER (SHORT) | D15: =IFERROR(__xludf.DUMMYFUNCTION("""COMPUTED_VALUE"""),1.0) -> 1 | E15: =IFERROR(__xludf.DUMMYFUNCTION("""COMPUTED_VALUE"""),0.0) -> 0
A16: =IFERROR(__xludf.DUMMYFUNCTION("""COMPUTED_VALUE"""),"ADMIN") -> ADMIN | B16: =IFERROR(__xludf.DUMMYFUNCTION("""COMPUTED_VALUE"""),"ITM004") -> ITM004 | C16: =IFERROR(__xludf.DUMMYFUNCTION("""COMPUTED_VALUE"""),"BOND PAPER NEWSPRINT (SHORT)") -> BOND PAPER NEWSPRINT (SHORT) | D16: =IFERROR(__xludf.DUMMYFUNCTION("""COMPUTED_VALUE"""),1.0) -> 1 | E16: =IFERROR(__xludf.DUMMYFUNCTION("""COMPUTED_VALUE"""),0.0) -> 0
A17: =IFERROR(__xludf.DUMMYFUNCTION("""COMPUTED_VALUE"""),"ADMIN") -> ADMIN | B17: =IFERROR(__xludf.DUMMYFUNCTION("""COMPUTED_VALUE"""),"ITM093") -> ITM093 | C17: =IFERROR(__xludf.DUMMYFUNCTION("""COMPUTED_VALUE"""),"TRASH BAG (XXL)") -> TRASH BAG (XXL) | D17: =IFERROR(__xludf.DUMMYFUNCTION("""COMPUTED_VALUE"""),1.0) -> 1 | E17: =IFERROR(__xludf.DUMMYFUNCTION("""COMPUTED_VALUE"""),0.0) -> 0
A18: =IFERROR(__xludf.DUMMYFUNCTION("""COMPUTED_VALUE"""),"ADMIN") -> ADMIN | B18: =IFERROR(__xludf.DUMMYFUNCTION("""COMPUTED_VALUE"""),"ITM095") -> ITM095 | C18: =IFERROR(__xludf.DUMMYFUNCTION("""COMPUTED_VALUE"""),"TRASH BAG (LARGE)") -> TRASH BAG (LARGE) | D18: =IFERROR(__xludf.DUMMYFUNCTION("""COMPUTED_VALUE"""),1.0) -> 1 | E18: =IFERROR(__xludf.DUMMYFUNCTION("""COMPUTED_VALUE"""),0.0) -> 0
A19: =IFERROR(__xludf.DUMMYFUNCTION("""COMPUTED_VALUE"""),"WAREHOUSE") -> WAREHOUSE | B19: =IFERROR(__xludf.DUMMYFUNCTION("""COMPUTED_VALUE"""),"ITM038") -> ITM038 | C19: =IFERROR(__xludf.DUMMYFUNCTION("""COMPUTED_VALUE"""),"MASKING TAPE") -> MASKING TAPE | D19: =IFERROR(__xludf.DUMMYFUNCTION("""COMPUTED_VALUE"""),3.0) -> 3 | E19: =IFERROR(__xludf.DUMMYFUNCTION("""COMPUTED_VALUE"""),0.0) -> 0
A20: =IFERROR(__xludf.DUMMYFUNCTION("""COMPUTED_VALUE"""),"WAREHOUSE") -> WAREHOUSE | B20: =IFERROR(__xludf.DUMMYFUNCTION("""COMPUTED_VALUE"""),"ITM056") -> ITM056 | C20: =IFERROR(__xludf.DUMMYFUNCTION("""COMPUTED_VALUE"""),"PRIDE SOAP POWDER") -> PRIDE SOAP POWDER | D20: =IFERROR(__xludf.DUMMYFUNCTION("""COMPUTED_VALUE"""),10.0) -> 10 | E20: =IFERROR(__xludf.DUMMYFUNCTION("""COMPUTED_VALUE"""),0.0) -> 0
A21: =IFERROR(__xludf.DUMMYFUNCTION("""COMPUTED_VALUE"""),"WAREHOUSE") -> WAREHOUSE | B21: =IFERROR(__xludf.DUMMYFUNCTION("""COMPUTED_VALUE"""),"ITM061") -> ITM061 | C21: =IFERROR(__xludf.DUMMYFUNCTION("""COMPUTED_VALUE"""),"JOY") -> JOY | D21: =IFERROR(__xludf.DUMMYFUNCTION("""COMPUTED_VALUE"""),3.0) -> 3 | E21: =IFERROR(__xludf.DUMMYFUNCTION("""COMPUTED_VALUE"""),0.0) -> 0
A22: =IFERROR(__xludf.DUMMYFUNCTION("""COMPUTED_VALUE"""),"WAREHOUSE") -> WAREHOUSE | B22: =IFERROR(__xludf.DUMMYFUNCTION("""COMPUTED_VALUE"""),"ITM002") -> ITM002 | C22: =IFERROR(__xludf.DUMMYFUNCTION("""COMPUTED_VALUE"""),"BOND PAPER (SHORT)") -> BOND PAPER (SHORT) | D22: =IFERROR(__xludf.DUMMYFUNCTION("""COMPUTED_VALUE"""),1.0) -> 1 | E22: =IFERROR(__xludf.DUMMYFUNCTION("""COMPUTED_VALUE"""),0.0) -> 0
A23: =IFERROR(__xludf.DUMMYFUNCTION("""COMPUTED_VALUE"""),"WAREHOUSE") -> WAREHOUSE | B23: =IFERROR(__xludf.DUMMYFUNCTION("""COMPUTED_VALUE"""),"ITM092") -> ITM092 | C23: =IFERROR(__xludf.DUMMYFUNCTION("""COMPUTED_VALUE"""),"RAGS") -> RAGS | D23: =IFERROR(__xludf.DUMMYFUNCTION("""COMPUTED_VALUE"""),1.0) -> 1 | E23: =IFERROR(__xludf.DUMMYFUNCTION("""COMPUTED_VALUE"""),0.0) -> 0
A24: =IFERROR(__xludf.DUMMYFUNCTION("""COMPUTED_VALUE"""),"WAREHOUSE") -> WAREHOUSE | B24: =IFERROR(__xludf.DUMMYFUNCTION("""COMPUTED_VALUE"""),"ITM079") -> ITM079 | C24: =IFERROR(__xludf.DUMMYFUNCTION("""COMPUTED_VALUE"""),"DRINKING CUPS") -> DRINKING CUPS | D24: =IFERROR(__xludf.DUMMYFUNCTION("""COMPUTED_VALUE"""),1.0) -> 1 | E24: =IFERROR(__xludf.DUMMYFUNCTION("""COMPUTED_VALUE"""),0.0) -> 0
A25: =IFERROR(__xludf.DUMMYFUNCTION("""COMPUTED_VALUE"""),"LAGTANG") -> LAGTANG | B25: =IFERROR(__xludf.DUMMYFUNCTION("""COMPUTED_VALUE"""),"ITM002") -> ITM002 | C25: =IFERROR(__xludf.DUMMYFUNCTION("""COMPUTED_VALUE"""),"BOND PAPER (SHORT)") -> BOND PAPER (SHORT) | D25: =IFERROR(__xludf.DUMMYFUNCTION("""COMPUTED_VALUE"""),1.0) -> 1 | E25: =IFERROR(__xludf.DUMMYFUNCTION("""COMPUTED_VALUE"""),0.0) -> 0
A26: =IFERROR(__xludf.DUMMYFUNCTION("""COMPUTED_VALUE"""),"LAGTANG") -> LAGTANG | B26: =IFERROR(__xludf.DUMMYFUNCTION("""COMPUTED_VALUE"""),"ITM012") -> ITM012 | C26: =IFERROR(__xludf.DUMMYFUNCTION("""COMPUTED_VALUE"""),"BROWN FOLDER (LONG)") -> BROWN FOLDER (LONG) | D26: =IFERROR(__xludf.DUMMYFUNCTION("""COMPUTED_VALUE"""),20.0) -> 20 | E26: =IFERROR(__xludf.DUMMYFUNCTION("""COMPUTED_VALUE"""),0.0) -> 0
A27: =IFERROR(__xludf.DUMMYFUNCTION("""COMPUTED_VALUE"""),"LAGTANG") -> LAGTANG | B27: =IFERROR(__xludf.DUMMYFUNCTION("""COMPUTED_VALUE"""),"ITM027") -> ITM027 | C27: =IFERROR(__xludf.DUMMYFUNCTION("""COMPUTED_VALUE"""),"CORRECTION TAPE") -> CORRECTION TAPE | D27: =IFERROR(__xludf.DUMMYFUNCTION("""COMPUTED_VALUE"""),2.0) -> 2 | E27: =IFERROR(__xludf.DUMMYFUNCTION("""COMPUTED_VALUE"""),0.0) -> 0
A28: =IFERROR(__xludf.DUMMYFUNCTION("""COMPUTED_VALUE"""),"LAGTANG") -> LAGTANG | B28: =IFERROR(__xludf.DUMMYFUNCTION("""COMPUTED_VALUE"""),"ITM062") -> ITM062 | C28: =IFERROR(__xludf.DUMMYFUNCTION("""COMPUTED_VALUE"""),"DOWNY") -> DOWNY | D28: =IFERROR(__xludf.DUMMYFUNCTION("""COMPUTED_VALUE"""),3.0) -> 3 | E28: =IFERROR(__xludf.DUMMYFUNCTION("""COMPUTED_VALUE"""),0.0) -> 0
A29: =IFERROR(__xludf.DUMMYFUNCTION("""COMPUTED_VALUE"""),"LAGTANG") -> LAGTANG | B29: =IFERROR(__xludf.DUMMYFUNCTION("""COMPUTED_VALUE"""),"ITM020") -> ITM020 | C29: =IFERROR(__xludf.DUMMYFUNCTION("""COMPUTED_VALUE"""),"FLEXSTICK RED BALLPEN (0.5)") -> FLEXSTICK RED BALLPEN (0.5) | D29: =IFERROR(__xludf.DUMMYFUNCTION("""COMPUTED_VALUE"""),5.0) -> 5 | E29: =IFERROR(__xludf.DUMMYFUNCTION("""COMPUTED_VALUE"""),0.0) -> 0
A30: =IFERROR(__xludf.DUMMYFUNCTION("""COMPUTED_VALUE"""),"LAGTANG") -> LAGTANG | B30: =IFERROR(__xludf.DUMMYFUNCTION("""COMPUTED_VALUE"""),"ITM023") -> ITM023 | C30: =IFERROR(__xludf.DUMMYFUNCTION("""COMPUTED_VALUE"""),"HIGHLIGHTER") -> HIGHLIGHTER | D30: =IFERROR(__xludf.DUMMYFUNCTION("""COMPUTED_VALUE"""),1.0) -> 1 | E30: =IFERROR(__xludf.DUMMYFUNCTION("""COMPUTED_VALUE"""),0.0) -> 0
A31: =IFERROR(__xludf.DUMMYFUNCTION("""COMPUTED_VALUE"""),"LAGTANG") -> LAGTANG | B31: =IFERROR(__xludf.DUMMYFUNCTION("""COMPUTED_VALUE"""),"ITM061") -> ITM061 | C31: =IFERROR(__xludf.DUMMYFUNCTION("""COMPUTED_VALUE"""),"JOY") -> JOY | D31: =IFERROR(__xludf.DUMMYFUNCTION("""COMPUTED_VALUE"""),3.0) -> 3 | E31: =IFERROR(__xludf.DUMMYFUNCTION("""COMPUTED_VALUE"""),0.0) -> 0
A32: =IFERROR(__xludf.DUMMYFUNCTION("""COMPUTED_VALUE"""),"LAGTANG") -> LAGTANG | B32: =IFERROR(__xludf.DUMMYFUNCTION("""COMPUTED_VALUE"""),"ITM038") -> ITM038 | C32: =IFERROR(__xludf.DUMMYFUNCTION("""COMPUTED_VALUE"""),"MASKING TAPE") -> MASKING TAPE | D32: =IFERROR(__xludf.DUMMYFUNCTION("""COMPUTED_VALUE"""),1.0) -> 1 | E32: =IFERROR(__xludf.DUMMYFUNCTION("""COMPUTED_VALUE"""),0.0) -> 0
A33: =IFERROR(__xludf.DUMMYFUNCTION("""COMPUTED_VALUE"""),"LAGTANG") -> LAGTANG | B33: =IFERROR(__xludf.DUMMYFUNCTION("""COMPUTED_VALUE"""),"ITM056") -> ITM056 | C33: =IFERROR(__xludf.DUMMYFUNCTION("""COMPUTED_VALUE"""),"PRIDE SOAP POWDER") -> PRIDE SOAP POWDER | D33: =IFERROR(__xludf.DUMMYFUNCTION("""COMPUTED_VALUE"""),6.0) -> 6 | E33: =IFERROR(__xludf.DUMMYFUNCTION("""COMPUTED_VALUE"""),0.0) -> 0
A34: =IFERROR(__xludf.DUMMYFUNCTION("""COMPUTED_VALUE"""),"LAGTANG") -> LAGTANG | B34: =IFERROR(__xludf.DUMMYFUNCTION("""COMPUTED_VALUE"""),"ITM063") -> ITM063 | C34: =IFERROR(__xludf.DUMMYFUNCTION("""COMPUTED_VALUE"""),"SAFEGUARD SOAP") -> SAFEGUARD SOAP | D34: =IFERROR(__xludf.DUMMYFUNCTION("""COMPUTED_VALUE"""),1.0) -> 1 | E34: =IFERROR(__xludf.DUMMYFUNCTION("""COMPUTED_VALUE"""),0.0) -> 0
A35: =IFERROR(__xludf.DUMMYFUNCTION("""COMPUTED_VALUE"""),"LAGTANG") -> LAGTANG | B35: =IFERROR(__xludf.DUMMYFUNCTION("""COMPUTED_VALUE"""),"ITM064") -> ITM064 | C35: =IFERROR(__xludf.DUMMYFUNCTION("""COMPUTED_VALUE"""),"STICKY NOTES 2X2 A02") -> STICKY NOTES 2X2 A02 | D35: =IFERROR(__xludf.DUMMYFUNCTION("""COMPUTED_VALUE"""),1.0) -> 1 | E35: =IFERROR(__xludf.DUMMYFUNCTION("""COMPUTED_VALUE"""),0.0) -> 0
A36: =IFERROR(__xludf.DUMMYFUNCTION("""COMPUTED_VALUE"""),"LAGTANG") -> LAGTANG | B36: =IFERROR(__xludf.DUMMYFUNCTION("""COMPUTED_VALUE"""),"ITM096") -> ITM096 | C36: =IFERROR(__xludf.DUMMYFUNCTION("""COMPUTED_VALUE"""),"TRASH BAG (MEDIUM)") -> TRASH BAG (MEDIUM) | D36: =IFERROR(__xludf.DUMMYFUNCTION("""COMPUTED_VALUE"""),1.0) -> 1 | E36: =IFERROR(__xludf.DUMMYFUNCTION("""COMPUTED_VALUE"""),0.0) -> 0
A37: =IFERROR(__xludf.DUMMYFUNCTION("""COMPUTED_VALUE"""),"LAGTANG") -> LAGTANG | B37: =IFERROR(__xludf.DUMMYFUNCTION("""COMPUTED_VALUE"""),"ITM006") -> ITM006 | C37: =IFERROR(__xludf.DUMMYFUNCTION("""COMPUTED_VALUE"""),"VELLUM PAPER") -> VELLUM PAPER | D37: =IFERROR(__xludf.DUMMYFUNCTION("""COMPUTED_VALUE"""),20.0) -> 20 | E37: =IFERROR(__xludf.DUMMYFUNCTION("""COMPUTED_VALUE"""),0.0) -> 0
A38: =IFERROR(__xludf.DUMMYFUNCTION("""COMPUTED_VALUE"""),"LAGTANG") -> LAGTANG | B38: =IFERROR(__xludf.DUMMYFUNCTION("""COMPUTED_VALUE"""),"ITM089") -> ITM089 | C38: =IFERROR(__xludf.DUMMYFUNCTION("""COMPUTED_VALUE"""),"ZONROX (COLORSAFE)") -> ZONROX (COLORSAFE) | D38: =IFERROR(__xludf.DUMMYFUNCTION("""COMPUTED_VALUE"""),1.0) -> 1 | E38: =IFERROR(__xludf.DUMMYFUNCTION("""COMPUTED_VALUE"""),0.0) -> 0
A39: =IFERROR(__xludf.DUMMYFUNCTION("""COMPUTED_VALUE"""),"LAGTANG") -> LAGTANG | B39: =IFERROR(__xludf.DUMMYFUNCTION("""COMPUTED_VALUE"""),"ITM003") -> ITM003 | C39: =IFERROR(__xludf.DUMMYFUNCTION("""COMPUTED_VALUE"""),"BOND PAPER A4") -> BOND PAPER A4 | D39: =IFERROR(__xludf.DUMMYFUNCTION("""COMPUTED_VALUE"""),1.0) -> 1 | E39: =IFERROR(__xludf.DUMMYFUNCTION("""COMPUTED_VALUE"""),0.0) -> 0
A40: =IFERROR(__xludf.DUMMYFUNCTION("""COMPUTED_VALUE"""),"LAGTANG") -> LAGTANG | B40: =IFERROR(__xludf.DUMMYFUNCTION("""COMPUTED_VALUE"""),"ITM010") -> ITM010 | C40: =IFERROR(__xludf.DUMMYFUNCTION("""COMPUTED_VALUE"""),"BROWN ENVELOPE (LONG)") -> BROWN ENVELOPE (LONG) | D40: =IFERROR(__xludf.DUMMYFUNCTION("""COMPUTED_VALUE"""),5.0) -> 5 | E40: =IFERROR(__xludf.DUMMYFUNCTION("""COMPUTED_VALUE"""),0.0) -> 0
...

Sheet ALL BRANCH APPROVED
A1: Timestamp | B1: Branch | C1: Date | D1: To | E1: Purpose | F1: ITEM_ID | G1: Qty | H1: Unit | I1: Description | J1: UPrice | K1: Amount | L1: Total | M1: Requested By | N1: Status | O1: Release Date | P1: Received By | Q1: PDF URL

Sheet RUNNING STOCKS
A1: Item_ID | B1: Description | C1: Unit | D1: ADMIN | E1: WAREHOUSE | F1: LAGTANG | G1: V-RAMA | H1: BULACAO | I1: Y3S TALISAY | J1: MINGLANILLA | K1: Y3S PARDO | L1: LAPU-LAPU | M1: BACAYAN | N1: SAN FERNANDO MB | O1: Y3S SAN FERNANDO | P1: LILOAN | Q1: CORDOVA MB | R1: Y3S CORDOVA | S1: CLARIN | T1: TOLEDO | U1: UBAY | V1: CARMEN | W1: TUBIGON | X1: TALIBON | Y1: BOGO | Z1: BALAMBAN | AA1: Y3S BARILI | AB1: BARILI MB | AC1: SIERRA BULLONES | AD1: PITOGO | AE1: TAYUD CONSOLACION | AF1: PINAMUNGAJAN | AG1: CANDIJAY | AH1: YATI LILOAN | AI1: CAMOTES | AJ1: Total Outgoing Stocks
A2: ITM001 | B2: BOND PAPER (LONG) | C2: REAM | D2: =IFERROR(SUMIFS(SUMMARY!D:D, SUMMARY!B:B, A2, SUMMARY!A:A, "ADMIN"), 0) -> 1 | E2: 0 | F2: =IFERROR(SUMIFS(SUMMARY!D:D, SUMMARY!B:B, A2, SUMMARY!A:A, "LAGTANG"), 0) -> 0 | G2: =IFERROR(SUMIFS(SUMMARY!D:D, SUMMARY!B:B, A2, SUMMARY!A:A, "V-RAMA"), 0) -> 1 | H2: =IFERROR(SUMIFS(SUMMARY!D:D, SUMMARY!B:B, A2, SUMMARY!A:A, "BULACAO"), 0) -> 0 | I2: =IFERROR(SUMIFS(SUMMARY!D:D, SUMMARY!B:B, A2, SUMMARY!A:A, "Y3S TALISAY"), 0) -> 0 | J2: =IFERROR(SUMIFS(SUMMARY!D:D, SUMMARY!B:B, A2, SUMMARY!A:A, "MINGLANILLA"), 0) -> 0 | K2: =IFERROR(SUMIFS(SUMMARY!D:D, SUMMARY!B:B, A2, SUMMARY!A:A, "Y3S PARDO"), 0) -> 0 | L2: =IFERROR(SUMIFS(SUMMARY!D:D, SUMMARY!B:B, A2, SUMMARY!A:A, "LAPU-LAPU"), 0) -> 0 | M2: =IFERROR(SUMIFS(SUMMARY!D:D, SUMMARY!B:B, A2, SUMMARY!A:A, "BACAYAN"), 0) -> 1 | N2: =IFERROR(SUMIFS(SUMMARY!D:D, SUMMARY!B:B, A2, SUMMARY!A:A, "SAN FERNANDO MB"), 0) -> 1 | O2: =IFERROR(SUMIFS(SUMMARY!D:D, SUMMARY!B:B, A2, SUMMARY!A:A, "Y3S SAN FERNANDO"), 0) -> 1 | P2: =IFERROR(SUMIFS(SUMMARY!D:D, SUMMARY!B:B, A2, SUMMARY!A:A, "LILOAN"), 0) -> 1 | Q2: =IFERROR(SUMIFS(SUMMARY!D:D, SUMMARY!B:B, A2, SUMMARY!A:A, "CORDOVA MB"), 0) -> 0 | R2: =IFERROR(SUMIFS(SUMMARY!D:D, SUMMARY!B:B, A2, SUMMARY!A:A, "Y3S CORDOVA"), 0) -> 1 | S2: =IFERROR(SUMIFS(SUMMARY!D:D, SUMMARY!B:B, A2, SUMMARY!A:A, "CLARIN"), 0) -> 0 | T2: =IFERROR(SUMIFS(SUMMARY!D:D, SUMMARY!B:B, A2, SUMMARY!A:A, "TOLEDO"), 0) -> 0 | U2: =IFERROR(SUMIFS(SUMMARY!D:D, SUMMARY!B:B, A2, SUMMARY!A:A, "UBAY"), 0) -> 0 | V2: =IFERROR(SUMIFS(SUMMARY!D:D, SUMMARY!B:B, A2, SUMMARY!A:A, "CARMEN"), 0) -> 1 | W2: =IFERROR(SUMIFS(SUMMARY!D:D, SUMMARY!B:B, A2, SUMMARY!A:A, "TUBIGON"), 0) -> 0 | X2: =IFERROR(SUMIFS(SUMMARY!D:D, SUMMARY!B:B, A2, SUMMARY!A:A, "TALIBON"), 0) -> 0 | Y2: =IFERROR(SUMIFS(SUMMARY!D:D, SUMMARY!B:B, A2, SUMMARY!A:A, "BOGO"), 0) -> 1 | Z2: =IFERROR(SUMIFS(SUMMARY!D:D, SUMMARY!B:B, A2, SUMMARY!A:A, "BALAMBAN"), 0) -> 0 | AA2: =IFERROR(SUMIFS(SUMMARY!D:D, SUMMARY!B:B, A2, SUMMARY!A:A, "Y3S BARILI"), 0) -> 1 | AB2: =IFERROR(SUMIFS(SUMMARY!D:D, SUMMARY!B:B, A2, SUMMARY!A:A, "BARILI MB"), 0) -> 1 | AC2: =IFERROR(SUMIFS(SUMMARY!D:D, SUMMARY!B:B, A2, SUMMARY!A:A, "SIERRA BULLONES"), 0) -> 1 | AD2: =IFERROR(SUMIFS(SUMMARY!D:D, SUMMARY!B:B, A2, SUMMARY!A:A, "PITOGO"), 0) -> 0 | AE2: =IFERROR(SUMIFS(SUMMARY!D:D, SUMMARY!B:B, A2, SUMMARY!A:A, "TAYUD CONSOLACION"), 0) -> 0 | AF2: =IFERROR(SUMIFS(SUMMARY!D:D, SUMMARY!B:B, A2, SUMMARY!A:A, "PINAMUNGAJAN"), 0) -> 0 | AG2: =IFERROR(SUMIFS(SUMMARY!D:D, SUMMARY!B:B, A2, SUMMARY!A:A, "CANDIJAY"), 0) -> 1 | AH2: =IFERROR(SUMIFS(SUMMARY!D:D, SUMMARY!B:B, A2, SUMMARY!A:A, "YATI LILOAN"), 0) -> 1 | AI2: =IFERROR(SUMIFS(SUMMARY!D:D, SUMMARY!B:B, A2, SUMMARY!A:A, "CAMOTES"), 0) -> 0 | AJ2: =SUM(D2:AH2) -> 14
A3: ITM002 | B3: BOND PAPER (SHORT) | C3: REAM | D3: =IFERROR(SUMIFS(SUMMARY!D:D, SUMMARY!B:B, A3, SUMMARY!A:A, "ADMIN"), 0) -> 2 | E3: =IFERROR(SUMIFS(SUMMARY!D:D, SUMMARY!B:B, A3, SUMMARY!A:A, "WAREHOUSE"), 0) -> 1 | F3: =IFERROR(SUMIFS(SUMMARY!D:D, SUMMARY!B:B, A3, SUMMARY!A:A, "LAGTANG"), 0) -> 1 | G3: =IFERROR(SUMIFS(SUMMARY!D:D, SUMMARY!B:B, A3, SUMMARY!A:A, "V-RAMA"), 0) -> 0 | H3: =IFERROR(SUMIFS(SUMMARY!D:D, SUMMARY!B:B, A3, SUMMARY!A:A, "BULACAO"), 0) -> 0 | I3: =IFERROR(SUMIFS(SUMMARY!D:D, SUMMARY!B:B, A3, SUMMARY!A:A, "Y3S TALISAY"), 0) -> 2 | J3: =IFERROR(SUMIFS(SUMMARY!D:D, SUMMARY!B:B, A3, SUMMARY!A:A, "MINGLANILLA"), 0) -> 1 | K3: =IFERROR(SUMIFS(SUMMARY!D:D, SUMMARY!B:B, A3, SUMMARY!A:A, "Y3S PARDO"), 0) -> 0 | L3: =IFERROR(SUMIFS(SUMMARY!D:D, SUMMARY!B:B, A3, SUMMARY!A:A, "LAPU-LAPU"), 0) -> 0 | M3: =IFERROR(SUMIFS(SUMMARY!D:D, SUMMARY!B:B, A3, SUMMARY!A:A, "BACAYAN"), 0) -> 0 | N3: =IFERROR(SUMIFS(SUMMARY!D:D, SUMMARY!B:B, A3, SUMMARY!A:A, "SAN FERNANDO MB"), 0) -> 1 | O3: =IFERROR(SUMIFS(SUMMARY!D:D, SUMMARY!B:B, A3, SUMMARY!A:A, "Y3S SAN FERNANDO"), 0) -> 1 | P3: =IFERROR(SUMIFS(SUMMARY!D:D, SUMMARY!B:B, A3, SUMMARY!A:A, "LILOAN"), 0) -> 1 | Q3: =IFERROR(SUMIFS(SUMMARY!D:D, SUMMARY!B:B, A3, SUMMARY!A:A, "CORDOVA MB"), 0) -> 0 | R3: =IFERROR(SUMIFS(SUMMARY!D:D, SUMMARY!B:B, A3, SUMMARY!A:A, "Y3S CORDOVA"), 0) -> 3 | S3: =IFERROR(SUMIFS(SUMMARY!D:D, SUMMARY!B:B, A3, SUMMARY!A:A, "CLARIN"), 0) -> 0 | T3: =IFERROR(SUMIFS(SUMMARY!D:D, SUMMARY!B:B, A3, SUMMARY!A:A, "TOLEDO"), 0) -> 0 | U3: =IFERROR(SUMIFS(SUMMARY!D:D, SUMMARY!B:B, A3, SUMMARY!A:A, "UBAY"), 0) -> 1 | V3: =IFERROR(SUMIFS(SUMMARY!D:D, SUMMARY!B:B, A3, SUMMARY!A:A, "CARMEN"), 0) -> 1 | W3: =IFERROR(SUMIFS(SUMMARY!D:D, SUMMARY!B:B, A3, SUMMARY!A:A, "TUBIGON"), 0) -> 1 | X3: =IFERROR(SUMIFS(SUMMARY!D:D, SUMMARY!B:B, A3, SUMMARY!A:A, "TALIBON"), 0) -> 1 | Y3: =IFERROR(SUMIFS(SUMMARY!D:D, SUMMARY!B:B, A3, SUMMARY!A:A, "BOGO"), 0) -> 0 | Z3: =IFERROR(SUMIFS(SUMMARY!D:D, SUMMARY!B:B, A3, SUMMARY!A:A, "BALAMBAN"), 0) -> 0 | AA3: =IFERROR(SUMIFS(SUMMARY!D:D, SUMMARY!B:B, A3, SUMMARY!A:A, "Y3S BARILI"), 0) -> 1 | AB3: =IFERROR(SUMIFS(SUMMARY!D:D, SUMMARY!B:B, A3, SUMMARY!A:A, "BARILI MB"), 0) -> 1 | AC3: =IFERROR(SUMIFS(SUMMARY!D:D, SUMMARY!B:B, A3, SUMMARY!A:A, "SIERRA BULLONES"), 0) -> 1 | AD3: =IFERROR(SUMIFS(SUMMARY!D:D, SUMMARY!B:B, A3, SUMMARY!A:A, "PITOGO"), 0) -> 1 | AE3: =IFERROR(SUMIFS(SUMMARY!D:D, SUMMARY!B:B, A3, SUMMARY!A:A, "TAYUD CONSOLACION"), 0) -> 0 | AF3: =IFERROR(SUMIFS(SUMMARY!D:D, SUMMARY!B:B, A3, SUMMARY!A:A, "PINAMUNGAJAN"), 0) -> 1 | AG3: =IFERROR(SUMIFS(SUMMARY!D:D, SUMMARY!B:B, A3, SUMMARY!A:A, "CANDIJAY"), 0) -> 1 | AH3: =IFERROR(SUMIFS(SUMMARY!D:D, SUMMARY!B:B, A3, SUMMARY!A:A, "YATI LILOAN"), 0) -> 1 | AI3: =IFERROR(SUMIFS(SUMMARY!D:D, SUMMARY!B:B, A3, SUMMARY!A:A, "CAMOTES"), 0) -> 0 | AJ3: =SUM(D3:AH3) -> 24
A4: ITM003 | B4: BOND PAPER A4 | C4: REAM | D4: =IFERROR(SUMIFS(SUMMARY!D:D, SUMMARY!B:B, A4, SUMMARY!A:A, "ADMIN"), 0) -> 1 | E4: =IFERROR(SUMIFS(SUMMARY!D:D, SUMMARY!B:B, A4, SUMMARY!A:A, "WAREHOUSE"), 0) -> 0 | F4: =IFERROR(SUMIFS(SUMMARY!D:D, SUMMARY!B:B, A4, SUMMARY!A:A, "LAGTANG"), 0) -> 1 | G4: =IFERROR(SUMIFS(SUMMARY!D:D, SUMMARY!B:B, A4, SUMMARY!A:A, "V-RAMA"), 0) -> 1 | H4: =IFERROR(SUMIFS(SUMMARY!D:D, SUMMARY!B:B, A4, SUMMARY!A:A, "BULACAO"), 0) -> 0 | I4: =IFERROR(SUMIFS(SUMMARY!D:D, SUMMARY!B:B, A4, SUMMARY!A:A, "Y3S TALISAY"), 0) -> 1 | J4: =IFERROR(SUMIFS(SUMMARY!D:D, SUMMARY!B:B, A4, SUMMARY!A:A, "MINGLANILLA"), 0) -> 0 | K4: =IFERROR(SUMIFS(SUMMARY!D:D, SUMMARY!B:B, A4, SUMMARY!A:A, "Y3S PARDO"), 0) -> 1 | L4: =IFERROR(SUMIFS(SUMMARY!D:D, SUMMARY!B:B, A4, SUMMARY!A:A, "LAPU-LAPU"), 0) -> 0 | M4: =IFERROR(SUMIFS(SUMMARY!D:D, SUMMARY!B:B, A4, SUMMARY!A:A, "BACAYAN"), 0) -> 0 | N4: =IFERROR(SUMIFS(SUMMARY!D:D, SUMMARY!B:B, A4, SUMMARY!A:A, "SAN FERNANDO MB"), 0) -> 0 | O4: =IFERROR(SUMIFS(SUMMARY!D:D, SUMMARY!B:B, A4, SUMMARY!A:A, "Y3S SAN FERNANDO"), 0) -> 0 | P4: =IFERROR(SUMIFS(SUMMARY!D:D, SUMMARY!B:B, A4, SUMMARY!A:A, "LILOAN"), 0) -> 0 | Q4: =IFERROR(SUMIFS(SUMMARY!D:D, SUMMARY!B:B, A4, SUMMARY!A:A, "CORDOVA MB"), 0) -> 0 | R4: =IFERROR(SUMIFS(SUMMARY!D:D, SUMMARY!B:B, A4, SUMMARY!A:A, "Y3S CORDOVA"), 0) -> 1 | S4: =IFERROR(SUMIFS(SUMMARY!D:D, SUMMARY!B:B, A4, SUMMARY!A:A, "CLARIN"), 0) -> 1 | T4: =IFERROR(SUMIFS(SUMMARY!D:D, SUMMARY!B:B, A4, SUMMARY!A:A, "TOLEDO"), 0) -> 0 | U4: =IFERROR(SUMIFS(SUMMARY!D:D, SUMMARY!B:B, A4, SUMMARY!A:A, "UBAY"), 0) -> 0 | V4: =IFERROR(SUMIFS(SUMMARY!D:D, SUMMARY!B:B, A4, SUMMARY!A:A, "CARMEN"), 0) -> 0 | W4: =IFERROR(SUMIFS(SUMMARY!D:D, SUMMARY!B:B, A4, SUMMARY!A:A, "TUBIGON"), 0) -> 0 | X4: =IFERROR(SUMIFS(SUMMARY!D:D, SUMMARY!B:B, A4, SUMMARY!A:A, "TALIBON"), 0) -> 0 | Y4: =IFERROR(SUMIFS(SUMMARY!D:D, SUMMARY!B:B, A4, SUMMARY!A:A, "BOGO"), 0) -> 1 | Z4: =IFERROR(SUMIFS(SUMMARY!D:D, SUMMARY!B:B, A4, SUMMARY!A:A, "BALAMBAN"), 0) -> 1 | AA4: =IFERROR(SUMIFS(SUMMARY!D:D, SUMMARY!B:B, A4, SUMMARY!A:A, "Y3S BARILI"), 0) -> 0 | AB4: =IFERROR(SUMIFS(SUMMARY!D:D, SUMMARY!B:B, A4, SUMMARY!A:A, "BARILI MB"), 0) -> 0 | AC4: =IFERROR(SUMIFS(SUMMARY!D:D, SUMMARY!B:B, A4, SUMMARY!A:A, "SIERRA BULLONES"), 0) -> 0 | AD4: =IFERROR(SUMIFS(SUMMARY!D:D, SUMMARY!B:B, A4, SUMMARY!A:A, "PITOGO"), 0) -> 0 | AE4: =IFERROR(SUMIFS(SUMMARY!D:D, SUMMARY!B:B, A4, SUMMARY!A:A, "TAYUD CONSOLACION"), 0) -> 0 | AF4: =IFERROR(SUMIFS(SUMMARY!D:D, SUMMARY!B:B, A4, SUMMARY!A:A, "PINAMUNGAJAN"), 0) -> 1 | AG4: =IFERROR(SUMIFS(SUMMARY!D:D, SUMMARY!B:B, A4, SUMMARY!A:A, "CANDIJAY"), 0) -> 0 | AH4: =IFERROR(SUMIFS(SUMMARY!D:D, SUMMARY!B:B, A4, SUMMARY!A:A, "YATI LILOAN"), 0) -> 0 | AI4: =IFERROR(SUMIFS(SUMMARY!D:D, SUMMARY!B:B, A4, SUMMARY!A:A, "CAMOTES"), 0) -> 0 | AJ4: =SUM(D4:AH4) -> 10
A5: ITM004 | B5: BOND PAPER NEWSPRINT (SHORT) | C5: REAM | D5: 0 | E5: =IFERROR(SUMIFS(SUMMARY!D:D, SUMMARY!B:B, A5, SUMMARY!A:A, "WAREHOUSE"), 0) -> 0 | F5: =IFERROR(SUMIFS(SUMMARY!D:D, SUMMARY!B:B, A5, SUMMARY!A:A, "LAGTANG"), 0) -> 0 | G5: =IFERROR(SUMIFS(SUMMARY!D:D, SUMMARY!B:B, A5, SUMMARY!A:A, "V-RAMA"), 0) -> 0 | H5: =IFERROR(SUMIFS(SUMMARY!D:D, SUMMARY!B:B, A5, SUMMARY!A:A, "BULACAO"), 0) -> 0 | I5: =IFERROR(SUMIFS(SUMMARY!D:D, SUMMARY!B:B, A5, SUMMARY!A:A, "Y3S TALISAY"), 0) -> 1 | J5: =IFERROR(SUMIFS(SUMMARY!D:D, SUMMARY!B:B, A5, SUMMARY!A:A, "MINGLANILLA"), 0) -> 0 | K5: =IFERROR(SUMIFS(SUMMARY!D:D, SUMMARY!B:B, A5, SUMMARY!A:A, "Y3S PARDO"), 0) -> 2 | L5: =IFERROR(SUMIFS(SUMMARY!D:D, SUMMARY!B:B, A5, SUMMARY!A:A, "LAPU-LAPU"), 0) -> 0 | M5: =IFERROR(SUMIFS(SUMMARY!D:D, SUMMARY!B:B, A5, SUMMARY!A:A, "BACAYAN"), 0) -> 1 | N5: =IFERROR(SUMIFS(SUMMARY!D:D, SUMMARY!B:B, A5, SUMMARY!A:A, "SAN FERNANDO MB"), 0) -> 0 | O5: =IFERROR(SUMIFS(SUMMARY!D:D, SUMMARY!B:B, A5, SUMMARY!A:A, "Y3S SAN FERNANDO"), 0) -> 0 | P5: =IFERROR(SUMIFS(SUMMARY!D:D, SUMMARY!B:B, A5, SUMMARY!A:A, "LILOAN"), 0) -> 1 | Q5: =IFERROR(SUMIFS(SUMMARY!D:D, SUMMARY!B:B, A5, SUMMARY!A:A, "CORDOVA MB"), 0) -> 0 | R5: =IFERROR(SUMIFS(SUMMARY!D:D, SUMMARY!B:B, A5, SUMMARY!A:A, "Y3S CORDOVA"), 0) -> 0 | S5: =IFERROR(SUMIFS(SUMMARY!D:D, SUMMARY!B:B, A5, SUMMARY!A:A, "CLARIN"), 0) -> 1 | T5: =IFERROR(SUMIFS(SUMMARY!D:D, SUMMARY!B:B, A5, SUMMARY!A:A, "TOLEDO"), 0) -> 0 | U5: =IFERROR(SUMIFS(SUMMARY!D:D, SUMMARY!B:B, A5, SUMMARY!A:A, "UBAY"), 0) -> 0 | V5: =IFERROR(SUMIFS(SUMMARY!D:D, SUMMARY!B:B, A5, SUMMARY!A:A, "CARMEN"), 0) -> 0 | W5: =IFERROR(SUMIFS(SUMMARY!D:D, SUMMARY!B:B, A5, SUMMARY!A:A, "TUBIGON"), 0) -> 0 | X5: =IFERROR(SUMIFS(SUMMARY!D:D, SUMMARY!B:B, A5, SUMMARY!A:A, "TALIBON"), 0) -> 0 | Y5: =IFERROR(SUMIFS(SUMMARY!D:D, SUMMARY!B:B, A5, SUMMARY!A:A, "BOGO"), 0) -> 0 | Z5: =IFERROR(SUMIFS(SUMMARY!D:D, SUMMARY!B:B, A5, SUMMARY!A:A, "BALAMBAN"), 0) -> 0 | AA5: =IFERROR(SUMIFS(SUMMARY!D:D, SUMMARY!B:B, A5, SUMMARY!A:A, "Y3S BARILI"), 0) -> 0 | AB5: =IFERROR(SUMIFS(SUMMARY!D:D, SUMMARY!B:B, A5, SUMMARY!A:A, "BARILI MB"), 0) -> 0 | AC5: =IFERROR(SUMIFS(SUMMARY!D:D, SUMMARY!B:B, A5, SUMMARY!A:A, "SIERRA BULLONES"), 0) -> 0 | AD5: =IFERROR(SUMIFS(SUMMARY!D:D, SUMMARY!B:B, A5, SUMMARY!A:A, "PITOGO"), 0) -> 0 | AE5: =IFERROR(SUMIFS(SUMMARY!D:D, SUMMARY!B:B, A5, SUMMARY!A:A, "TAYUD CONSOLACION"), 0) -> 1 | AF5: =IFERROR(SUMIFS(SUMMARY!D:D, SUMMARY!B:B, A5, SUMMARY!A:A, "PINAMUNGAJAN"), 0) -> 0 | AG5: =IFERROR(SUMIFS(SUMMARY!D:D, SUMMARY!B:B, A5, SUMMARY!A:A, "CANDIJAY"), 0) -> 0 | AH5: 0 | AI5: =IFERROR(SUMIFS(SUMMARY!D:D, SUMMARY!B:B, A5, SUMMARY!A:A, "CAMOTES"), 0) -> 0 | AJ5: =SUM(D5:AH5) -> 7
A6: ITM005 | B6: BOND PAPER NEWSPRINT (LONG) | C6: REAM | D6: =IFERROR(SUMIFS(SUMMARY!D:D, SUMMARY!B:B, A6, SUMMARY!A:A, "ADMIN"), 0) -> 0 | E6: =IFERROR(SUMIFS(SUMMARY!D:D, SUMMARY!B:B, A6, SUMMARY!A:A, "WAREHOUSE"), 0) -> 0 | F6: =IFERROR(SUMIFS(SUMMARY!D:D, SUMMARY!B:B, A6, SUMMARY!A:A, "LAGTANG"), 0) -> 0 | G6: =IFERROR(SUMIFS(SUMMARY!D:D, SUMMARY!B:B, A6, SUMMARY!A:A, "V-RAMA"), 0) -> 0 | H6: =IFERROR(SUMIFS(SUMMARY!D:D, SUMMARY!B:B, A6, SUMMARY!A:A, "BULACAO"), 0) -> 0 | I6: =IFERROR(SUMIFS(SUMMARY!D:D, SUMMARY!B:B, A6, SUMMARY!A:A, "Y3S TALISAY"), 0) -> 0 | J6: =IFERROR(SUMIFS(SUMMARY!D:D, SUMMARY!B:B, A6, SUMMARY!A:A, "MINGLANILLA"), 0) -> 0 | K6: =IFERROR(SUMIFS(SUMMARY!D:D, SUMMARY!B:B, A6, SUMMARY!A:A, "Y3S PARDO"), 0) -> 2 | L6: =IFERROR(SUMIFS(SUMMARY!D:D, SUMMARY!B:B, A6, SUMMARY!A:A, "LAPU-LAPU"), 0) -> 0 | M6: =IFERROR(SUMIFS(SUMMARY!D:D, SUMMARY!B:B, A6, SUMMARY!A:A, "BACAYAN"), 0) -> 0 | N6: =IFERROR(SUMIFS(SUMMARY!D:D, SUMMARY!B:B, A6, SUMMARY!A:A, "SAN FERNANDO MB"), 0) -> 0 | O6: =IFERROR(SUMIFS(SUMMARY!D:D, SUMMARY!B:B, A6, SUMMARY!A:A, "Y3S SAN FERNANDO"), 0) -> 0 | P6: =IFERROR(SUMIFS(SUMMARY!D:D, SUMMARY!B:B, A6, SUMMARY!A:A, "LILOAN"), 0) -> 0 | Q6: =IFERROR(SUMIFS(SUMMARY!D:D, SUMMARY!B:B, A6, SUMMARY!A:A, "CORDOVA MB"), 0) -> 0 | R6: =IFERROR(SUMIFS(SUMMARY!D:D, SUMMARY!B:B, A6, SUMMARY!A:A, "Y3S CORDOVA"), 0) -> 0 | S6: =IFERROR(SUMIFS(SUMMARY!D:D, SUMMARY!B:B, A6, SUMMARY!A:A, "CLARIN"), 0) -> 1 | T6: =IFERROR(SUMIFS(SUMMARY!D:D, SUMMARY!B:B, A6, SUMMARY!A:A, "TOLEDO"), 0) -> 0 | U6: =IFERROR(SUMIFS(SUMMARY!D:D, SUMMARY!B:B, A6, SUMMARY!A:A, "UBAY"), 0) -> 0 | V6: =IFERROR(SUMIFS(SUMMARY!D:D, SUMMARY!B:B, A6, SUMMARY!A:A, "CARMEN"), 0) -> 0 | W6: =IFERROR(SUMIFS(SUMMARY!D:D, SUMMARY!B:B, A6, SUMMARY!A:A, "TUBIGON"), 0) -> 0 | X6: =IFERROR(SUMIFS(SUMMARY!D:D, SUMMARY!B:B, A6, SUMMARY!A:A, "TALIBON"), 0) -> 0 | Y6: =IFERROR(SUMIFS(SUMMARY!D:D, SUMMARY!B:B, A6, SUMMARY!A:A, "BOGO"), 0) -> 0 | Z6: =IFERROR(SUMIFS(SUMMARY!D:D, SUMMARY!B:B, A6, SUMMARY!A:A, "BALAMBAN"), 0) -> 1 | AA6: =IFERROR(SUMIFS(SUMMARY!D:D, SUMMARY!B:B, A6, SUMMARY!A:A, "Y3S BARILI"), 0) -> 0 | AB6: =IFERROR(SUMIFS(SUMMARY!D:D, SUMMARY!B:B, A6, SUMMARY!A:A, "BARILI MB"), 0) -> 0 | AC6: =IFERROR(SUMIFS(SUMMARY!D:D, SUMMARY!B:B, A6, SUMMARY!A:A, "SIERRA BULLONES"), 0) -> 0 | AD6: =IFERROR(SUMIFS(SUMMARY!D:D, SUMMARY!B:B, A6, SUMMARY!A:A, "PITOGO"), 0) -> 0 | AE6: =IFERROR(SUMIFS(SUMMARY!D:D, SUMMARY!B:B, A6, SUMMARY!A:A, "TAYUD CONSOLACION"), 0) -> 0 | AF6: =IFERROR(SUMIFS(SUMMARY!D:D, SUMMARY!B:B, A6, SUMMARY!A:A, "PINAMUNGAJAN"), 0) -> 0 | AG6: =IFERROR(SUMIFS(SUMMARY!D:D, SUMMARY!B:B, A6, SUMMARY!A:A, "CANDIJAY"), 0) -> 0 | AH6: =IFERROR(SUMIFS(SUMMARY!D:D, SUMMARY!B:B, A6, SUMMARY!A:A, "YATI LILOAN"), 0) -> 0 | AI6: =IFERROR(SUMIFS(SUMMARY!D:D, SUMMARY!B:B, A6, SUMMARY!A:A, "CAMOTES"), 0) -> 0 | AJ6: =SUM(D6:AH6) -> 4
A7: ITM006 | B7: VELLUM PAPER | C7: PC | D7: =IFERROR(SUMIFS(SUMMARY!D:D, SUMMARY!B:B, A7, SUMMARY!A:A, "ADMIN"), 0) -> 0 | E7: =IFERROR(SUMIFS(SUMMARY!D:D, SUMMARY!B:B, A7, SUMMARY!A:A, "WAREHOUSE"), 0) -> 0 | F7: =IFERROR(SUMIFS(SUMMARY!D:D, SUMMARY!B:B, A7, SUMMARY!A:A, "LAGTANG"), 0) -> 45 | G7: =IFERROR(SUMIFS(SUMMARY!D:D, SUMMARY!B:B, A7, SUMMARY!A:A, "V-RAMA"), 0) -> 20 | H7: =IFERROR(SUMIFS(SUMMARY!D:D, SUMMARY!B:B, A7, SUMMARY!A:A, "BULACAO"), 0) -> 0 | I7: =IFERROR(SUMIFS(SUMMARY!D:D, SUMMARY!B:B, A7, SUMMARY!A:A, "Y3S TALISAY"), 0) -> 0 | J7: =IFERROR(SUMIFS(SUMMARY!D:D, SUMMARY!B:B, A7, SUMMARY!A:A, "MINGLANILLA"), 0) -> 30 | K7: =IFERROR(SUMIFS(SUMMARY!D:D, SUMMARY!B:B, A7, SUMMARY!A:A, "Y3S PARDO"), 0) -> 30 | L7: =IFERROR(SUMIFS(SUMMARY!D:D, SUMMARY!B:B, A7, SUMMARY!A:A, "LAPU-LAPU"), 0) -> 0 | M7: =IFERROR(SUMIFS(SUMMARY!D:D, SUMMARY!B:B, A7, SUMMARY!A:A, "BACAYAN"), 0) -> 20 | N7: =IFERROR(SUMIFS(SUMMARY!D:D, SUMMARY!B:B, A7, SUMMARY!A:A, "SAN FERNANDO MB"), 0) -> 0 | O7: =IFERROR(SUMIFS(SUMMARY!D:D, SUMMARY!B:B, A7, SUMMARY!A:A, "Y3S SAN FERNANDO"), 0) -> 0 | P7: =IFERROR(SUMIFS(SUMMARY!D:D, SUMMARY!B:B, A7, SUMMARY!A:A, "LILOAN"), 0) -> 30 | Q7: =IFERROR(SUMIFS(SUMMARY!D:D, SUMMARY!B:B, A7, SUMMARY!A:A, "CORDOVA MB"), 0) -> 10 | R7: =IFERROR(SUMIFS(SUMMARY!D:D, SUMMARY!B:B, A7, SUMMARY!A:A, "Y3S CORDOVA"), 0) -> 70 | S7: =IFERROR(SUMIFS(SUMMARY!D:D, SUMMARY!B:B, A7, SUMMARY!A:A, "CLARIN"), 0) -> 40 | T7: =IFERROR(SUMIFS(SUMMARY!D:D, SUMMARY!B:B, A7, SUMMARY!A:A, "TOLEDO"), 0) -> 30 | U7: =IFERROR(SUMIFS(SUMMARY!D:D, SUMMARY!B:B, A7, SUMMARY!A:A, "UBAY"), 0) -> 20 | V7: =IFERROR(SUMIFS(SUMMARY!D:D, SUMMARY!B:B, A7, SUMMARY!A:A, "CARMEN"), 0) -> 30 | W7: =IFERROR(SUMIFS(SUMMARY!D:D, SUMMARY!B:B, A7, SUMMARY!A:A, "TUBIGON"), 0) -> 30 | X7: =IFERROR(SUMIFS(SUMMARY!D:D, SUMMARY!B:B, A7, SUMMARY!A:A, "TALIBON"), 0) -> 30 | Y7: =IFERROR(SUMIFS(SUMMARY!D:D, SUMMARY!B:B, A7, SUMMARY!A:A, "BOGO"), 0) -> 30 | Z7: =IFERROR(SUMIFS(SUMMARY!D:D, SUMMARY!B:B, A7, SUMMARY!A:A, "BALAMBAN"), 0) -> 15 | AA7: =IFERROR(SUMIFS(SUMMARY!D:D, SUMMARY!B:B, A7, SUMMARY!A:A, "Y3S BARILI"), 0) -> 0 | AB7: =IFERROR(SUMIFS(SUMMARY!D:D, SUMMARY!B:B, A7, SUMMARY!A:A, "BARILI MB"), 0) -> 20 | AC7: =IFERROR(SUMIFS(SUMMARY!D:D, SUMMARY!B:B, A7, SUMMARY!A:A, "SIERRA BULLONES"), 0) -> 0 | AD7: =IFERROR(SUMIFS(SUMMARY!D:D, SUMMARY!B:B, A7, SUMMARY!A:A, "PITOGO"), 0) -> 0 | AE7: =IFERROR(SUMIFS(SUMMARY!D:D, SUMMARY!B:B, A7, SUMMARY!A:A, "TAYUD CONSOLACION"), 0) -> 0 | AF7: =IFERROR(SUMIFS(SUMMARY!D:D, SUMMARY!B:B, A7, SUMMARY!A:A, "PINAMUNGAJAN"), 0) -> 20 | AG7: =IFERROR(SUMIFS(SUMMARY!D:D, SUMMARY!B:B, A7, SUMMARY!A:A, "CANDIJAY"), 0) -> 20 | AH7: =IFERROR(SUMIFS(SUMMARY!D:D, SUMMARY!B:B, A7, SUMMARY!A:A, "YATI LILOAN"), 0) -> 0 | AI7: =IFERROR(SUMIFS(SUMMARY!D:D, SUMMARY!B:B, A7, SUMMARY!A:A, "CAMOTES"), 0) -> 0 | AJ7: =SUM(D7:AH7) -> 540
A8: ITM007 | B8: LOGBOOK VALIANT RECORD (150 & 300P PAGES) | C8: PC | D8: =IFERROR(SUMIFS(SUMMARY!D:D, SUMMARY!B:B, A8, SUMMARY!A:A, "ADMIN"), 0) -> 1 | E8: =IFERROR(SUMIFS(SUMMARY!D:D, SUMMARY!B:B, A8, SUMMARY!A:A, "WAREHOUSE"), 0) -> 0 | F8: =IFERROR(SUMIFS(SUMMARY!D:D, SUMMARY!B:B, A8, SUMMARY!A:A, "LAGTANG"), 0) -> 0 | G8: =IFERROR(SUMIFS(SUMMARY!D:D, SUMMARY!B:B, A8, SUMMARY!A:A, "V-RAMA"), 0) -> 0 | H8: =IFERROR(SUMIFS(SUMMARY!D:D, SUMMARY!B:B, A8, SUMMARY!A:A, "BULACAO"), 0) -> 0 | I8: =IFERROR(SUMIFS(SUMMARY!D:D, SUMMARY!B:B, A8, SUMMARY!A:A, "Y3S TALISAY"), 0) -> 0 | J8: =IFERROR(SUMIFS(SUMMARY!D:D, SUMMARY!B:B, A8, SUMMARY!A:A, "MINGLANILLA"), 0) -> 0 | K8: =IFERROR(SUMIFS(SUMMARY!D:D, SUMMARY!B:B, A8, SUMMARY!A:A, "Y3S PARDO"), 0) -> 0 | L8: =IFERROR(SUMIFS(SUMMARY!D:D, SUMMARY!B:B, A8, SUMMARY!A:A, "LAPU-LAPU"), 0) -> 0 | M8: =IFERROR(SUMIFS(SUMMARY!D:D, SUMMARY!B:B, A8, SUMMARY!A:A, "BACAYAN"), 0) -> 0 | N8: =IFERROR(SUMIFS(SUMMARY!D:D, SUMMARY!B:B, A8, SUMMARY!A:A, "SAN FERNANDO MB"), 0) -> 0 | O8: =IFERROR(SUMIFS(SUMMARY!D:D, SUMMARY!B:B, A8, SUMMARY!A:A, "Y3S SAN FERNANDO"), 0) -> 0 | P8: =IFERROR(SUMIFS(SUMMARY!D:D, SUMMARY!B:B, A8, SUMMARY!A:A, "LILOAN"), 0) -> 1 | Q8: =IFERROR(SUMIFS(SUMMARY!D:D, SUMMARY!B:B, A8, SUMMARY!A:A, "CORDOVA MB"), 0) -> 0 | R8: =IFERROR(SUMIFS(SUMMARY!D:D, SUMMARY!B:B, A8, SUMMARY!A:A, "Y3S CORDOVA"), 0) -> 0 | S8: =IFERROR(SUMIFS(SUMMARY!D:D, SUMMARY!B:B, A8, SUMMARY!A:A, "CLARIN"), 0) -> 0 | T8: =IFERROR(SUMIFS(SUMMARY!D:D, SUMMARY!B:B, A8, SUMMARY!A:A, "TOLEDO"), 0) -> 0 | U8: =IFERROR(SUMIFS(SUMMARY!D:D, SUMMARY!B:B, A8, SUMMARY!A:A, "UBAY"), 0) -> 0 | V8: =IFERROR(SUMIFS(SUMMARY!D:D, SUMMARY!B:B, A8, SUMMARY!A:A, "CARMEN"), 0) -> 0 | W8: =IFERROR(SUMIFS(SUMMARY!D:D, SUMMARY!B:B, A8, SUMMARY!A:A, "TUBIGON"), 0) -> 0 | X8: =IFERROR(SUMIFS(SUMMARY!D:D, SUMMARY!B:B, A8, SUMMARY!A:A, "TALIBON"), 0) -> 0 | Y8: =IFERROR(SUMIFS(SUMMARY!D:D, SUMMARY!B:B, A8, SUMMARY!A:A, "BOGO"), 0) -> 0 | Z8: =IFERROR(SUMIFS(SUMMARY!D:D, SUMMARY!B:B, A8, SUMMARY!A:A, "BALAMBAN"), 0) -> 0 | AA8: =IFERROR(SUMIFS(SUMMARY!D:D, SUMMARY!B:B, A8, SUMMARY!A:A, "Y3S BARILI"), 0) -> 1 | AB8: =IFERROR(SUMIFS(SUMMARY!D:D, SUMMARY!B:B, A8, SUMMARY!A:A, "BARILI MB"), 0) -> 0 | AC8: =IFERROR(SUMIFS(SUMMARY!D:D, SUMMARY!B:B, A8, SUMMARY!A:A, "SIERRA BULLONES"), 0) -> 0 | AD8: =IFERROR(SUMIFS(SUMMARY!D:D, SUMMARY!B:B, A8, SUMMARY!A:A, "PITOGO"), 0) -> 0 | AE8: =IFERROR(SUMIFS(SUMMARY!D:D, SUMMARY!B:B, A8, SUMMARY!A:A, "TAYUD CONSOLACION"), 0) -> 0 | AF8: =IFERROR(SUMIFS(SUMMARY!D:D, SUMMARY!B:B, A8, SUMMARY!A:A, "PINAMUNGAJAN"), 0) -> 0 | AG8: =IFERROR(SUMIFS(SUMMARY!D:D, SUMMARY!B:B, A8, SUMMARY!A:A, "CANDIJAY"), 0) -> 0 | AH8: =IFERROR(SUMIFS(SUMMARY!D:D, SUMMARY!B:B, A8, SUMMARY!A:A, "YATI LILOAN"), 0) -> 0 | AI8: =IFERROR(SUMIFS(SUMMARY!D:D, SUMMARY!B:B, A8, SUMMARY!A:A, "CAMOTES"), 0) -> 0 | AJ8: =SUM(D8:AH8) -> 3
